Workbook

Sheet Table_Complete_CGNC_PCG
A1: TABLE DE CORRESPONDANCE COMPLÈTE PLAN COMPTABLE MAROCAIN (CGNC) → PCG FRANCE (ANC 2026)
A2: Sources : CGNC Maroc (9 classes) + PCG France ANC v.2026 | ✓ correspondance directe | ≈ approchée | ⚠ différence notable | ✗ sans équivalent PCG
A3: Cl. CGNC | B3: N° Cpt Maroc | C3: Intitulé Compte Marocain (CGNC) | D3: Statut | E3: N° Cpt France | F3: Intitulé Compte Français (PCG) | G3: Cl. PCG | H3: Observations / Divergences | I3: Clé recherche (sans zéros fin)
A4: CLASSE 1 — COMPTES DE FINANCEMENT PERMANENT (CGNC) → CLASSE 1 — COMPTES DE CAPITAUX (PCG)
A5: 1 | B5: 111 | C5: Capital social ou personnel | D5: ✓ | E5: 101 | F5: Capital | G5: 1 | H5: Identique | I5: 111
A6: 1 | B6: 1111 | C6: Capital social | D6: ✓ | E6: 1013 | F6: Capital souscrit - appelé, versé | G6: 1 | H6: Correspondance directe | I6: 1111
A7: 1 | B7: 1112 | C7: Fonds de dotation | D7: ≈ | E7: 108 | F7: Compte de l'exploitant | G7: 1 | H7: Spécifique associations marocaines | I7: 1112
A8: 1 | B8: 1117 | C8: Capital personnel | D8: ≈ | E8: 108 | F8: Compte de l'exploitant | G8: 1 | H8: EI/profession libérale | I8: 1117
A9: 1 | B9: 1119 | C9: Actionnaires, capital souscrit non appelé | D9: ✓ | E9: 109 | F9: Actionnaires : capital souscrit - non appelé | G9: 1 | H9: Identique - solde déducteur | I9: 1119
A10: 1 | B10: 112 | C10: Primes d'émission, de fusion et d'apport | D10: ✓ | E10: 104 | F10: Primes liées au capital | G10: 1 | H10: Même nature | I10: 112
A11: 1 | B11: 1121 | C11: Primes d'émission | D11: ✓ | E11: 1041 | F11: Primes d'émission | G11: 1 | H11: Identique | I11: 1121
A12: 1 | B12: 1122 | C12: Primes de fusion | D12: ✓ | E12: 1042 | F12: Primes de fusion | G12: 1 | H12: Identique | I12: 1122
A13: 1 | B13: 1123 | C13: Primes d'apport | D13: ✓ | E13: 1043 | F13: Primes d'apport | G13: 1 | H13: Identique | I13: 1123
A14: 1 | B14: 113 | C14: Ecarts de réévaluation | D14: ✓ | E14: 105 | F14: Écarts de réévaluation | G14: 1 | H14: Identique | I14: 113
A15: 1 | B15: 114 | C15: Réserve légale | D15: ✓ | E15: 1061 | F15: Réserve légale | G15: 1 | H15: Identique | I15: 114
A16: 1 | B16: 115 | C16: Autres réserves | D16: ✓ | E16: 106 | F16: Réserves | G16: 1 | H16: Regroupement en 106 France | I16: 115
... A58: 1 | B58: 172 | C58: Diminution des dettes de financement (écart conv.) | D58: ⚠ | E58: 4772 | F58: Diminution des dettes | G58: 4 | H58: ⚠ Maroc : cl.1 - France : cl.4 - reclassement nécessaire | I58: 172
A59: CLASSE 2 — COMPTES D'ACTIF IMMOBILISÉ (CGNC) → CLASSE 2 — COMPTES D'IMMOBILISATIONS (PCG)
A60: 2 | B60: 2111 | C60: Frais de constitution | D60: ⚠ | E60: 2011 | F60: Frais de constitution | G60: 2 | H60: ⚠ France : activation possible mais PCG préconise passage en charges - choix de méthode à documenter | I60: 2111
A61: 2 | B61: 2112 | C61: Frais préalables au démarrage | D61: ⚠ | E61: 2012 | F61: Frais de premier établissement | G61: 2 | H61: France : 20121 prospection ou 20122 publicité selon nature | I61: 2112
A62: 2 | B62: 2113 | C62: Frais d'augmentation du capital | D62: ✓ | E62: 2013 | F62: Frais d'augmentation de capital et opérations diverses | G62: 2 | H62: Identique | I62: 2113
A63: 2 | B63: 2114 | C63: Frais sur fusions, scissions, transformations | D63: ✓ | E63: 2013 | F63: Frais d'augmentation de capital et opérations diverses | G63: 2 | H63: Identique | I63: 2114
A64: 2 | B64: 2116 | C64: Frais de prospection | D64: ✓ | E64: 20121 | F64: Frais de prospection | G64: 2 | H64: Identique | I64: 2116
A65: 2 | B65: 2117 | C65: Frais de publicité | D65: ✓ | E65: 20122 | F65: Frais de publicité | G65: 2 | H65: Identique | I65: 2117
A66: 2 | B66: 2118 | C66: Autres frais préliminaires | D66: ≈ | E66: 2012 | F66: Frais de premier établissement | G66: 2 | H66: À ventiler selon nature | I66: 2118
A67: 2 | B67: 212 | C67: Charges à répartir sur plusieurs exercices | D67: ⚠ | E67: 486 | F67: Charges constatées d'avance | G67: 4 | H67: ⚠ France : pas d'actif distinct - CCA en 486 (cl.4) ou frais émission en 481 | I67: 212
A68: 2 | B68: 2121 | C68: Frais d'acquisition des immobilisations | D68: ⚠ | E68: 2xxx | F68: Inclus dans le coût d'acquisition de l'immobilisation | G68: 2 | H68: ⚠ PCG Art.213-8 : frais accessoires incorporés au coût - pas de compte séparé | I68: 2121
A69: 2 | B69: 2125 | C69: Frais d'émission des emprunts | D69: ✓ | E69: 481 | F69: Frais d'émission des emprunts | G69: 4 | H69: France : compte de régularisation actif (cl.4) - Maroc : actif immobilisé (cl.2) | I69: 2125
A70: 2 | B70: 213 | C70: Primes de remboursement des obligations | D70: ⚠ | E70: 169 | F70: Primes de remboursement des emprunts | G70: 1 | H70: ⚠ Maroc : actif immobilisé cl.2 - France : déducteur du passif cl.1 (169) | I70: 213
A71: 2 | B71: 221 | C71: Immobilisation en recherche et développement | D71: ✓ | E71: 203 | F71: Frais de développement | G71: 2 | H71: ⚠ France Art.212-3 : critères IAS 38 stricts - Maroc : critères moins détaillés | I71: 221
... A124: 2 | B124: 2958 | C124: Provisions pour dépréciation des autres titres | D124: ✓ | E124: 2971 | F124: Titres immobilisés | G124: 2 | H124: Identique | I124: 2958
A125: CLASSE 3 — ACTIF CIRCULANT HORS TRÉSORERIE (CGNC) → CLASSES 3 ET 4 (PCG) — DIFFÉRENCE ARCHITECTURALE MAJEURE
A126: 3 | B126: 311 | C126: Marchandises | D126: ✓ | E126: 37 | F126: Stocks de marchandises | G126: 3 | H126: Identique | I126: 311
A127: 3 | B127: 3121 | C127: Matières premières | D127: ✓ | E127: 31 | F127: Matières premières et fournitures | G127: 3 | H127: Identique | I127: 3121
A128: 3 | B128: 3122 | C128: Matières et fournitures consommables | D128: ✓ | E128: 321 | F128: Matières consommables | G128: 3 | H128: Identique | I128: 3122
A129: 3 | B129: 31223 | C129: Combustibles | D129: ✓ | E129: 3221 | F129: Combustibles | G129: 3 | H129: Identique | I129: 31223
A130: 3 | B130: 31224 | C130: Produits d'entretien | D130: ✓ | E130: 3222 | F130: Produits d'entretien | G130: 3 | H130: Identique | I130: 31224
A131: 3 | B131: 31225 | C131: Fournitures d'atelier et d'usine | D131: ✓ | E131: 3223 | F131: Fournitures d'atelier et d'usine | G131: 3 | H131: Identique | I131: 31225
A132: 3 | B132: 3123 | C132: Emballages | D132: ✓ | E132: 326 | F132: Emballages | G132: 3 | H132: Identique | I132: 3123
A133: 3 | B133: 313 | C133: Produits en cours | D133: ✓ | E133: 33 | F133: En-cours de production de biens | G133: 3 | H133: Identique | I133: 313
...

Sheet Conversion_Balance retravail ba
A1: OUTIL DE CONVERSION AUTOMATIQUE BALANCE MAROCAINE (CGNC / MAD) → BALANCE FRANÇAISE (PCG / EUR)
A2: PARAMÈTRE TAUX DE CHANGE | C2: 10.8 | D2: Source : Bank Al-Maghrib Cours moyen | G2: ⚠ Modifiez uniquement la cellule E2 pour actualiser tous les montants en euros. Tous les calculs EUR sont dynamiques.
A3: ▼ COLLER votre balance ici (colonnes A à F) : N° compte | Intitulé | Mvt Débit | Mvt Crédit | Solde Débiteur | Solde Créditeur | F3: ▼ RÉSULTAT AUTOMATIQUE (Ne pas modifier ces colonnes)
A4: N° Compte Maroc (CGNC) | B4: Intitulé Compte Marocain | C4: Solde Débiteur (MAD) | D4: Solde Créditeur (MAD) | F4: N° Compte France (PCG) | G4: Intitulé Compte Français (PCG) | H4: Solde Débiteur (EUR) | I4: Solde Créditeur (EUR) | K4: Alertes / Points de vigilance | L4: Clé_norm
A5: 111100 | B5: Capital social | D5: 100000 | F5: =IF(A5="","",IFERROR(INDEX(Table_Complete_CGNC_PCG!$E:$E,MATCH(L5,Table_Complete_CGNC_PCG!$I:$I,0)),"? Non trouvé")) -> 1013 | G5: =IF(A5="","",IFERROR(INDEX(Table_Complete_CGNC_PCG!$F:$F,MATCH(L5,Table_Complete_CGNC_PCG!$I:$I,0)),"Non trouve — ajouter dans la table")) -> Capital souscrit - appelé, versé | H5: =IF(OR(A5="",C5="",C5=0),"",ROUND(C5/$C$2,2)) | I5: =IF(OR(A5="",D5="",D5=0),"",ROUND(D5/$C$2,2)) -> 9259.26 | K5: =IF(A5="","",IFERROR(IF(F5="? Non mappe","Compte non trouve - mapper manuellement",IF(AND(ISNUMBER(SEARCH("516",L5)),D5>0),"CAISSE CREDITRICE - anomalie a corriger",IF(IFERROR(INDEX(Table_Complete_CGNC_PCG!$D:$D,MATCH(L5,Table_Complete_CGNC_PCG!$I:$I,0)),"")="?","Retraitement requis - voir table","OK"))),"Erreur")) -> OK | L5: =LEFT(TEXT(A5,"0"),4) -> 1111
A6: 116100 | B6: Résultat net de l'exercice | D6: 861409.18 | F6: =IF(A6="","",IFERROR(INDEX(Table_Complete_CGNC_PCG!$E:$E,MATCH(L6,Table_Complete_CGNC_PCG!$I:$I,0)),"? Non trouvé")) -> 110 | G6: =IF(A6="","",IFERROR(INDEX(Table_Complete_CGNC_PCG!$F:$F,MATCH(L6,Table_Complete_CGNC_PCG!$I:$I,0)),"Non trouve — ajouter dans la table")) -> Report à nouveau - solde créditeur | H6: =IF(OR(A6="",C6="",C6=0),"",ROUND(C6/$C$2,2)) | I6: =IF(OR(A6="",D6="",D6=0),"",ROUND(D6/$C$2,2)) -> 79760.11 | K6: =IF(A6="","",IFERROR(IF(F6="? Non mappe","Compte non trouve - mapper manuellement",IF(AND(ISNUMBER(SEARCH("516",L6)),D6>0),"CAISSE CREDITRICE - anomalie a corriger",IF(IFERROR(INDEX(Table_Complete_CGNC_PCG!$D:$D,MATCH(L6,Table_Complete_CGNC_PCG!$I:$I,0)),"")="?","Retraitement requis - voir table","OK"))),"Erreur")) -> OK | L6: =LEFT(TEXT(A6,"0"),4) -> 1161
A7: 114100 | B7: Reserve légale | D7: 20000 | F7: =IF(A7="","",IFERROR(INDEX(Table_Complete_CGNC_PCG!$E:$E,MATCH(L7,Table_Complete_CGNC_PCG!$I:$I,0)),"? Non trouvé")) -> 1061 | G7: =IF(A7="","",IFERROR(INDEX(Table_Complete_CGNC_PCG!$F:$F,MATCH(L7,Table_Complete_CGNC_PCG!$I:$I,0)),"Non trouve — ajouter dans la table")) -> Réserve légale | H7: =IF(OR(A7="",C7="",C7=0),"",ROUND(C7/$C$2,2)) | I7: =IF(OR(A7="",D7="",D7=0),"",ROUND(D7/$C$2,2)) -> 1851.85 | K7: =IF(A7="","",IFERROR(IF(F7="? Non mappe","Compte non trouve - mapper manuellement",IF(AND(ISNUMBER(SEARCH("516",L7)),D7>0),"CAISSE CREDITRICE - anomalie a corriger",IF(IFERROR(INDEX(Table_Complete_CGNC_PCG!$D:$D,MATCH(L7,Table_Complete_CGNC_PCG!$I:$I,0)),"")="?","Retraitement requis - voir table","OK"))),"Erreur")) -> OK | L7: =LEFT(TEXT(A7,"0"),3) -> 114
A8: 211100 | B8: Frais de constitution | C8: 8200 | F8: =IF(A8="","",IFERROR(INDEX(Table_Complete_CGNC_PCG!$E:$E,MATCH(L8,Table_Complete_CGNC_PCG!$I:$I,0)),"? Non trouvé")) -> 2011 | G8: =IF(A8="","",IFERROR(INDEX(Table_Complete_CGNC_PCG!$F:$F,MATCH(L8,Table_Complete_CGNC_PCG!$I:$I,0)),"Non trouve — ajouter dans la table")) -> Frais de constitution | H8: =IF(OR(A8="",C8="",C8=0),"",ROUND(C8/$C$2,2)) -> 759.26 | I8: =IF(OR(A8="",D8="",D8=0),"",ROUND(D8/$C$2,2)) | K8: =IF(A8="","",IFERROR(IF(F8="? Non mappe","Compte non trouve - mapper manuellement",IF(AND(ISNUMBER(SEARCH("516",L8)),D8>0),"CAISSE CREDITRICE - anomalie a corriger",IF(IFERROR(INDEX(Table_Complete_CGNC_PCG!$D:$D,MATCH(L8,Table_Complete_CGNC_PCG!$I:$I,0)),"")="?","Retraitement requis - voir table","OK"))),"Erreur")) -> OK | L8: =LEFT(TEXT(A8,"0"),4) -> 2111
A9: 235600 | B9: Agencement, installation et aménagements divers | C9: 89830.33 | F9: =IF(A9="","",IFERROR(INDEX(Table_Complete_CGNC_PCG!$E:$E,MATCH(L9,Table_Complete_CGNC_PCG!$I:$I,0)),"? Non trouvé")) -> 2181 | G9: =IF(A9="","",IFERROR(INDEX(Table_Complete_CGNC_PCG!$F:$F,MATCH(L9,Table_Complete_CGNC_PCG!$I:$I,0)),"Non trouve — ajouter dans la table")) -> Installations générales, agencements, aménagements divers | H9: =IF(OR(A9="",C9="",C9=0),"",ROUND(C9/$C$2,2)) -> 8317.62 | I9: =IF(OR(A9="",D9="",D9=0),"",ROUND(D9/$C$2,2)) | K9: =IF(A9="","",IFERROR(IF(F9="? Non mappe","Compte non trouve - mapper manuellement",IF(AND(ISNUMBER(SEARCH("516",L9)),D9>0),"CAISSE CREDITRICE - anomalie a corriger",IF(IFERROR(INDEX(Table_Complete_CGNC_PCG!$D:$D,MATCH(L9,Table_Complete_CGNC_PCG!$I:$I,0)),"")="?","Retraitement requis - voir table","OK"))),"Erreur")) -> OK | L9: =LEFT(TEXT(A9,"0"),4) -> 2356
A10: 283500 | B10: Amortissements agencement - instalation | D10: 4045.36 | F10: =IF(A10="","",IFERROR(INDEX(Table_Complete_CGNC_PCG!$E:$E,MATCH(L10,Table_Complete_CGNC_PCG!$I:$I,0)),"? Non trouvé")) -> 2818 | G10: =IF(A10="","",IFERROR(INDEX(Table_Complete_CGNC_PCG!$F:$F,MATCH(L10,Table_Complete_CGNC_PCG!$I:$I,0)),"Non trouve — ajouter dans la table")) -> Autres immobilisations corporelles | H10: =IF(OR(A10="",C10="",C10=0),"",ROUND(C10/$C$2,2)) | I10: =IF(OR(A10="",D10="",D10=0),"",ROUND(D10/$C$2,2)) -> 374.57 | K10: =IF(A10="","",IFERROR(IF(F10="? Non mappe","Compte non trouve - mapper manuellement",IF(AND(ISNUMBER(SEARCH("516",L10)),D10>0),"CAISSE CREDITRICE - anomalie a corriger",IF(IFERROR(INDEX(Table_Complete_CGNC_PCG!$D:$D,MATCH(L10,Table_Complete_CGNC_PCG!$I:$I,0)),"")="?","Retraitement requis - voir table","OK"))),"Erreur")) -> OK | L10: =LEFT(TEXT(A10,"0"),4) -> 2835
A11: 281110 | B11: Amortissements des frais de constitution | D11: 3462.22 | F11: =IF(A11="","",IFERROR(INDEX(Table_Complete_CGNC_PCG!$E:$E,MATCH(L11,Table_Complete_CGNC_PCG!$I:$I,0)),"? Non trouvé")) -> 2801 | G11: =IF(A11="","",IFERROR(INDEX(Table_Complete_CGNC_PCG!$F:$F,MATCH(L11,Table_Complete_CGNC_PCG!$I:$I,0)),"Non trouve — ajouter dans la table")) -> Frais d'établissement (amortissements) | H11: =IF(OR(A11="",C11="",C11=0),"",ROUND(C11/$C$2,2)) | I11: =IF(OR(A11="",D11="",D11=0),"",ROUND(D11/$C$2,2)) -> 320.58 | K11: =IF(A11="","",IFERROR(IF(F11="? Non mappe","Compte non trouve - mapper manuellement",IF(AND(ISNUMBER(SEARCH("516",L11)),D11>0),"CAISSE CREDITRICE - anomalie a corriger",IF(IFERROR(INDEX(Table_Complete_CGNC_PCG!$D:$D,MATCH(L11,Table_Complete_CGNC_PCG!$I:$I,0)),"")="?","Retraitement requis - voir table","OK"))),"Erreur")) -> OK | L11: =LEFT(TEXT(A11,"0"),5) -> 28111
A12: 342100 | B12: Clients | C12: 202876.35 | F12: =IF(A12="","",IFERROR(INDEX(Table_Complete_CGNC_PCG!$E:$E,MATCH(L12,Table_Complete_CGNC_PCG!$I:$I,0)),"? Non trouvé")) -> 411 | G12: =IF(A12="","",IFERROR(INDEX(Table_Complete_CGNC_PCG!$F:$F,MATCH(L12,Table_Complete_CGNC_PCG!$I:$I,0)),"Non trouve — ajouter dans la table")) -> Clients | H12: =IF(OR(A12="",C12="",C12=0),"",ROUND(C12/$C$2,2)) -> 18784.85 | I12: =IF(OR(A12="",D12="",D12=0),"",ROUND(D12/$C$2,2)) | K12: =IF(A12="","",IFERROR(IF(F12="? Non mappe","Compte non trouve - mapper manuellement",IF(AND(ISNUMBER(SEARCH("516",L12)),D12>0),"CAISSE CREDITRICE - anomalie a corriger",IF(IFERROR(INDEX(Table_Complete_CGNC_PCG!$D:$D,MATCH(L12,Table_Complete_CGNC_PCG!$I:$I,0)),"")="?","Retraitement requis - voir table","OK"))),"Erreur")) -> OK | L12: =LEFT(TEXT(A12,"0"),4) -> 3421
A13: 3455200 | B13: ETAT - TVA récupérable sur les charges | C13: 2461.72 | F13: =IF(A13="","",IFERROR(INDEX(Table_Complete_CGNC_PCG!$E:$E,MATCH(L13,Table_Complete_CGNC_PCG!$I:$I,0)),"? Non trouvé")) -> 44566 | G13: =IF(A13="","",IFERROR(INDEX(Table_Complete_CGNC_PCG!$F:$F,MATCH(L13,Table_Complete_CGNC_PCG!$I:$I,0)),"Non trouve — ajouter dans la table")) -> TVA sur autres biens et services | H13: =IF(OR(A13="",C13="",C13=0),"",ROUND(C13/$C$2,2)) -> 227.94 | I13: =IF(OR(A13="",D13="",D13=0),"",ROUND(D13/$C$2,2)) | K13: =IF(A13="","",IFERROR(IF(F13="? Non mappe","Compte non trouve - mapper manuellement",IF(AND(ISNUMBER(SEARCH("516",L13)),D13>0),"CAISSE CREDITRICE - anomalie a corriger",IF(IFERROR(INDEX(Table_Complete_CGNC_PCG!$D:$D,MATCH(L13,Table_Complete_CGNC_PCG!$I:$I,0)),"")="?","Retraitement requis - voir table","OK"))),"Erreur")) -> OK | L13: =LEFT(TEXT(A13,"0"),5) -> 34552
A14: 441100 | B14: Fournisseurs A | D14: 9856 | F14: =IF(A14="","",IFERROR(INDEX(Table_Complete_CGNC_PCG!$E:$E,MATCH(L14,Table_Complete_CGNC_PCG!$I:$I,0)),"? Non trouvé")) -> 401 | G14: =IF(A14="","",IFERROR(INDEX(Table_Complete_CGNC_PCG!$F:$F,MATCH(L14,Table_Complete_CGNC_PCG!$I:$I,0)),"Non trouve — ajouter dans la table")) -> Fournisseurs | H14: =IF(OR(A14="",C14="",C14=0),"",ROUND(C14/$C$2,2)) | I14: =IF(OR(A14="",D14="",D14=0),"",ROUND(D14/$C$2,2)) -> 912.59 | K14: =IF(A14="","",IFERROR(IF(F14="? Non mappe","Compte non trouve - mapper manuellement",IF(AND(ISNUMBER(SEARCH("516",L14)),D14>0),"CAISSE CREDITRICE - anomalie a corriger",IF(IFERROR(INDEX(Table_Complete_CGNC_PCG!$D:$D,MATCH(L14,Table_Complete_CGNC_PCG!$I:$I,0)),"")="?","Retraitement requis - voir table","OK"))),"Erreur")) -> OK | L14: =LEFT(TEXT(A14,"0"),4) -> 4411
A15: 4411010 | B15: Fournisseurs B | D15: 4484.9 | F15: =IF(A15="","",IFERROR(INDEX(Table_Complete_CGNC_PCG!$E:$E,MATCH(L15,Table_Complete_CGNC_PCG!$I:$I,0)),"? Non trouvé")) -> 401 | G15: =IF(A15="","",IFERROR(INDEX(Table_Complete_CGNC_PCG!$F:$F,MATCH(L15,Table_Complete_CGNC_PCG!$I:$I,0)),"Non trouve — ajouter dans la table")) -> Fournisseurs | H15: =IF(OR(A15="",C15="",C15=0),"",ROUND(C15/$C$2,2)) | I15: =IF(OR(A15="",D15="",D15=0),"",ROUND(D15/$C$2,2)) -> 415.27 | K15: =IF(A15="","",IFERROR(IF(F15="? Non mappe","Compte non trouve - mapper manuellement",IF(AND(ISNUMBER(SEARCH("516",L15)),D15>0),"CAISSE CREDITRICE - anomalie a corriger",IF(IFERROR(INDEX(Table_Complete_CGNC_PCG!$D:$D,MATCH(L15,Table_Complete_CGNC_PCG!$I:$I,0)),"")="?","Retraitement requis - voir table","OK"))),"Erreur")) -> OK | L15: =LEFT(TEXT(A15,"0"),4) -> 4411
A16: 4411020 | B16: Fournisseurs C | D16: 3306.48 | F16: =IF(A16="","",IFERROR(INDEX(Table_Complete_CGNC_PCG!$E:$E,MATCH(L16,Table_Complete_CGNC_PCG!$I:$I,0)),"? Non trouvé")) -> 401 | G16: =IF(A16="","",IFERROR(INDEX(Table_Complete_CGNC_PCG!$F:$F,MATCH(L16,Table_Complete_CGNC_PCG!$I:$I,0)),"Non trouve — ajouter dans la table")) -> Fournisseurs | H16: =IF(OR(A16="",C16="",C16=0),"",ROUND(C16/$C$2,2)) | I16: =IF(OR(A16="",D16="",D16=0),"",ROUND(D16/$C$2,2)) -> 306.16 | K16: =IF(A16="","",IFERROR(IF(F16="? Non mappe","Compte non trouve - mapper manuellement",IF(AND(ISNUMBER(SEARCH("516",L16)),D16>0),"CAISSE CREDITRICE - anomalie a corriger",IF(IFERROR(INDEX(Table_Complete_CGNC_PCG!$D:$D,MATCH(L16,Table_Complete_CGNC_PCG!$I:$I,0)),"")="?","Retraitement requis - voir table","OK"))),"Erreur")) -> OK | L16: =LEFT(TEXT(A16,"0"),4) -> 4411
A17: 4411030 | B17: Fournisseurs D | D17: 997.93 | F17: =IF(A17="","",IFERROR(INDEX(Table_Complete_CGNC_PCG!$E:$E,MATCH(L17,Table_Complete_CGNC_PCG!$I:$I,0)),"? Non trouvé")) -> 401 | G17: =IF(A17="","",IFERROR(INDEX(Table_Complete_CGNC_PCG!$F:$F,MATCH(L17,Table_Complete_CGNC_PCG!$I:$I,0)),"Non trouve — ajouter dans la table")) -> Fournisseurs | H17: =IF(OR(A17="",C17="",C17=0),"",ROUND(C17/$C$2,2)) | I17: =IF(OR(A17="",D17="",D17=0),"",ROUND(D17/$C$2,2)) -> 92.4 | K17: =IF(A17="","",IFERROR(IF(F17="? Non mappe","Compte non trouve - mapper manuellement",IF(AND(ISNUMBER(SEARCH("516",L17)),D17>0),"CAISSE CREDITRICE - anomalie a corriger",IF(IFERROR(INDEX(Table_Complete_CGNC_PCG!$D:$D,MATCH(L17,Table_Complete_CGNC_PCG!$I:$I,0)),"")="?","Retraitement requis - voir table","OK"))),"Erreur")) -> OK | L17: =LEFT(TEXT(A17,"0"),4) -> 4411
A18: 4411040 | B18: Fournisseurs E | D18: 1116.34 | F18: =IF(A18="","",IFERROR(INDEX(Table_Complete_CGNC_PCG!$E:$E,MATCH(L18,Table_Complete_CGNC_PCG!$I:$I,0)),"? Non trouvé")) -> 401 | G18: =IF(A18="","",IFERROR(INDEX(Table_Complete_CGNC_PCG!$F:$F,MATCH(L18,Table_Complete_CGNC_PCG!$I:$I,0)),"Non trouve — ajouter dans la table")) -> Fournisseurs | H18: =IF(OR(A18="",C18="",C18=0),"",ROUND(C18/$C$2,2)) | I18: =IF(OR(A18="",D18="",D18=0),"",ROUND(D18/$C$2,2)) -> 103.36 | K18: =IF(A18="","",IFERROR(IF(F18="? Non mappe","Compte non trouve - mapper manuellement",IF(AND(ISNUMBER(SEARCH("516",L18)),D18>0),"CAISSE CREDITRICE - anomalie a corriger",IF(IFERROR(INDEX(Table_Complete_CGNC_PCG!$D:$D,MATCH(L18,Table_Complete_CGNC_PCG!$I:$I,0)),"")="?","Retraitement requis - voir table","OK"))),"Erreur")) -> OK | L18: =LEFT(TEXT(A18,"0"),4) -> 4411
A19: 4411050 | B19: Fournisseurs F | D19: 1925.77 | F19: =IF(A19="","",IFERROR(INDEX(Table_Complete_CGNC_PCG!$E:$E,MATCH(L19,Table_Complete_CGNC_PCG!$I:$I,0)),"? Non trouvé")) -> 401 | G19: =IF(A19="","",IFERROR(INDEX(Table_Complete_CGNC_PCG!$F:$F,MATCH(L19,Table_Complete_CGNC_PCG!$I:$I,0)),"Non trouve — ajouter dans la table")) -> Fournisseurs | H19: =IF(OR(A19="",C19="",C19=0),"",ROUND(C19/$C$2,2)) | I19: =IF(OR(A19="",D19="",D19=0),"",ROUND(D19/$C$2,2)) -> 178.31 | K19: =IF(A19="","",IFERROR(IF(F19="? Non mappe","Compte non trouve - mapper manuellement",IF(AND(ISNUMBER(SEARCH("516",L19)),D19>0),"CAISSE CREDITRICE - anomalie a corriger",IF(IFERROR(INDEX(Table_Complete_CGNC_PCG!$D:$D,MATCH(L19,Table_Complete_CGNC_PCG!$I:$I,0)),"")="?","Retraitement requis - voir table","OK"))),"Erreur")) -> OK | L19: =LEFT(TEXT(A19,"0"),4) -> 4411
A20: 4411060 | B20: Fournisseurs G | D20: 1443.51 | F20: =IF(A20="","",IFERROR(INDEX(Table_Complete_CGNC_PCG!$E:$E,MATCH(L20,Table_Complete_CGNC_PCG!$I:$I,0)),"? Non trouvé")) -> 401 | G20: =IF(A20="","",IFERROR(INDEX(Table_Complete_CGNC_PCG!$F:$F,MATCH(L20,Table_Complete_CGNC_PCG!$I:$I,0)),"Non trouve — ajouter dans la table")) -> Fournisseurs | H20: =IF(OR(A20="",C20="",C20=0),"",ROUND(C20/$C$2,2)) | I20: =IF(OR(A20="",D20="",D20=0),"",ROUND(D20/$C$2,2)) -> 133.66 | K20: =IF(A20="","",IFERROR(IF(F20="? Non mappe","Compte non trouve - mapper manuellement",IF(AND(ISNUMBER(SEARCH("516",L20)),D20>0),"CAISSE CREDITRICE - anomalie a corriger",IF(IFERROR(INDEX(Table_Complete_CGNC_PCG!$D:$D,MATCH(L20,Table_Complete_CGNC_PCG!$I:$I,0)),"")="?","Retraitement requis - voir table","OK"))),"Erreur")) -> OK | L20: =LEFT(TEXT(A20,"0"),4) -> 4411
A21: 4411070 | B21: Fournisseurs H | D21: 3950 | F21: =IF(A21="","",IFERROR(INDEX(Table_Complete_CGNC_PCG!$E:$E,MATCH(L21,Table_Complete_CGNC_PCG!$I:$I,0)),"? Non trouvé")) -> 401 | G21: =IF(A21="","",IFERROR(INDEX(Table_Complete_CGNC_PCG!$F:$F,MATCH(L21,Table_Complete_CGNC_PCG!$I:$I,0)),"Non trouve — ajouter dans la table")) -> Fournisseurs | H21: =IF(OR(A21="",C21="",C21=0),"",ROUND(C21/$C$2,2)) | I21: =IF(OR(A21="",D21="",D21=0),"",ROUND(D21/$C$2,2)) -> 365.74 | K21: =IF(A21="","",IFERROR(IF(F21="? Non mappe","Compte non trouve - mapper manuellement",IF(AND(ISNUMBER(SEARCH("516",L21)),D21>0),"CAISSE CREDITRICE - anomalie a corriger",IF(IFERROR(INDEX(Table_Complete_CGNC_PCG!$D:$D,MATCH(L21,Table_Complete_CGNC_PCG!$I:$I,0)),"")="?","Retraitement requis - voir table","OK"))),"Erreur")) -> OK | L21: =LEFT(TEXT(A21,"0"),4) -> 4411
A22: 4417000 | B22: Fournisseurs - factures non parvenues | D22: 1450.67 | F22: =IF(A22="","",IFERROR(INDEX(Table_Complete_CGNC_PCG!$E:$E,MATCH(L22,Table_Complete_CGNC_PCG!$I:$I,0)),"? Non trouvé")) -> 408 | G22: =IF(A22="","",IFERROR(INDEX(Table_Complete_CGNC_PCG!$F:$F,MATCH(L22,Table_Complete_CGNC_PCG!$I:$I,0)),"Non trouve — ajouter dans la table")) -> Fournisseurs - Factures non parvenues | H22: =IF(OR(A22="",C22="",C22=0),"",ROUND(C22/$C$2,2)) | I22: =IF(OR(A22="",D22="",D22=0),"",ROUND(D22/$C$2,2)) -> 134.32 | K22: =IF(A22="","",IFERROR(IF(F22="? Non mappe","Compte non trouve - mapper manuellement",IF(AND(ISNUMBER(SEARCH("516",L22)),D22>0),"CAISSE CREDITRICE - anomalie a corriger",IF(IFERROR(INDEX(Table_Complete_CGNC_PCG!$D:$D,MATCH(L22,Table_Complete_CGNC_PCG!$I:$I,0)),"")="?","Retraitement requis - voir table","OK"))),"Erreur")) -> OK | L22: =LEFT(TEXT(A22,"0"),4) -> 4417
A23: 4432000 | B23: Rémunérations dues au personnel | D23: 17321.28 | F23: =IF(A23="","",IFERROR(INDEX(Table_Complete_CGNC_PCG!$E:$E,MATCH(L23,Table_Complete_CGNC_PCG!$I:$I,0)),"? Non trouvé")) -> 421 | G23: =IF(A23="","",IFERROR(INDEX(Table_Complete_CGNC_PCG!$F:$F,MATCH(L23,Table_Complete_CGNC_PCG!$I:$I,0)),"Non trouve — ajouter dans la table")) -> Personnel - Rémunérations dues | H23: =IF(OR(A23="",C23="",C23=0),"",ROUND(C23/$C$2,2)) | I23: =IF(OR(A23="",D23="",D23=0),"",ROUND(D23/$C$2,2)) -> 1603.82 | K23: =IF(A23="","",IFERROR(IF(F23="? Non mappe","Compte non trouve - mapper manuellement",IF(AND(ISNUMBER(SEARCH("516",L23)),D23>0),"CAISSE CREDITRICE - anomalie a corriger",IF(IFERROR(INDEX(Table_Complete_CGNC_PCG!$D:$D,MATCH(L23,Table_Complete_CGNC_PCG!$I:$I,0)),"")="?","Retraitement requis - voir table","OK"))),"Erreur")) -> OK | L23: =LEFT(TEXT(A23,"0"),4) -> 4432
A24: 4455000 | B24: Etat, TVA facturée | C24: 33723.85 | F24: =IF(A24="","",IFERROR(INDEX(Table_Complete_CGNC_PCG!$E:$E,MATCH(L24,Table_Complete_CGNC_PCG!$I:$I,0)),"? Non trouvé")) -> 44571 | G24: =IF(A24="","",IFERROR(INDEX(Table_Complete_CGNC_PCG!$F:$F,MATCH(L24,Table_Complete_CGNC_PCG!$I:$I,0)),"Non trouve — ajouter dans la table")) -> TVA collectée | H24: =IF(OR(A24="",C24="",C24=0),"",ROUND(C24/$C$2,2)) -> 3122.58 | I24: =IF(OR(A24="",D24="",D24=0),"",ROUND(D24/$C$2,2)) | K24: =IF(A24="","",IFERROR(IF(F24="? Non mappe","Compte non trouve - mapper manuellement",IF(AND(ISNUMBER(SEARCH("516",L24)),D24>0),"CAISSE CREDITRICE - anomalie a corriger",IF(IFERROR(INDEX(Table_Complete_CGNC_PCG!$D:$D,MATCH(L24,Table_Complete_CGNC_PCG!$I:$I,0)),"")="?","Retraitement requis - voir table","OK"))),"Erreur")) -> OK | L24: =LEFT(TEXT(A24,"0"),4) -> 4455
A25: 4457000 | B25: Etat taxe de séjour | D25: 19598.65 | F25: =IF(A25="","",IFERROR(INDEX(Table_Complete_CGNC_PCG!$E:$E,MATCH(L25,Table_Complete_CGNC_PCG!$I:$I,0)),"? Non trouvé")) -> 447 | G25: =IF(A25="","",IFERROR(INDEX(Table_Complete_CGNC_PCG!$F:$F,MATCH(L25,Table_Complete_CGNC_PCG!$I:$I,0)),"Non trouve — ajouter dans la table")) -> Autres impôts, taxes et versements assimilés | H25: =IF(OR(A25="",C25="",C25=0),"",ROUND(C25/$C$2,2)) | I25: =IF(OR(A25="",D25="",D25=0),"",ROUND(D25/$C$2,2)) -> 1814.69 | K25: =IF(A25="","",IFERROR(IF(F25="? Non mappe","Compte non trouve - mapper manuellement",IF(AND(ISNUMBER(SEARCH("516",L25)),D25>0),"CAISSE CREDITRICE - anomalie a corriger",IF(IFERROR(INDEX(Table_Complete_CGNC_PCG!$D:$D,MATCH(L25,Table_Complete_CGNC_PCG!$I:$I,0)),"")="?","Retraitement requis - voir table","OK"))),"Erreur")) -> OK | L25: =LEFT(TEXT(A25,"0"),4) -> 4457
A26: 4456000 | B26: Etat, TVA due | D26: 48500 | F26: =IF(A26="","",IFERROR(INDEX(Table_Complete_CGNC_PCG!$E:$E,MATCH(L26,Table_Complete_CGNC_PCG!$I:$I,0)),"? Non trouvé")) -> 44551 | G26: =IF(A26="","",IFERROR(INDEX(Table_Complete_CGNC_PCG!$F:$F,MATCH(L26,Table_Complete_CGNC_PCG!$I:$I,0)),"Non trouve — ajouter dans la table")) -> TVA à décaisser | H26: =IF(OR(A26="",C26="",C26=0),"",ROUND(C26/$C$2,2)) | I26: =IF(OR(A26="",D26="",D26=0),"",ROUND(D26/$C$2,2)) -> 4490.74 | K26: =IF(A26="","",IFERROR(IF(F26="? Non mappe","Compte non trouve - mapper manuellement",IF(AND(ISNUMBER(SEARCH("516",L26)),D26>0),"CAISSE CREDITRICE - anomalie a corriger",IF(IFERROR(INDEX(Table_Complete_CGNC_PCG!$D:$D,MATCH(L26,Table_Complete_CGNC_PCG!$I:$I,0)),"")="?","Retraitement requis - voir table","OK"))),"Erreur")) -> OK | L26: =LEFT(TEXT(A26,"0"),4) -> 4456
A27: 4463000 | B27: Comptes courants des associés créditeurs | D27: 98270.5 | F27: =IF(A27="","",IFERROR(INDEX(Table_Complete_CGNC_PCG!$E:$E,MATCH(L27,Table_Complete_CGNC_PCG!$I:$I,0)),"? Non trouvé")) -> 455 | G27: =IF(A27="","",IFERROR(INDEX(Table_Complete_CGNC_PCG!$F:$F,MATCH(L27,Table_Complete_CGNC_PCG!$I:$I,0)),"Non trouve — ajouter dans la table")) -> Associés - Comptes courants | H27: =IF(OR(A27="",C27="",C27=0),"",ROUND(C27/$C$2,2)) | I27: =IF(OR(A27="",D27="",D27=0),"",ROUND(D27/$C$2,2)) -> 9099.12 | K27: =IF(A27="","",IFERROR(IF(F27="? Non mappe","Compte non trouve - mapper manuellement",IF(AND(ISNUMBER(SEARCH("516",L27)),D27>0),"CAISSE CREDITRICE - anomalie a corriger",IF(IFERROR(INDEX(Table_Complete_CGNC_PCG!$D:$D,MATCH(L27,Table_Complete_CGNC_PCG!$I:$I,0)),"")="?","Retraitement requis - voir table","OK"))),"Erreur")) -> OK | L27: =LEFT(TEXT(A27,"0"),4) -> 4463
A28: 5141000 | B28: Banques (ATIJARI WAFABANK) | C28: 951383.74 | F28: =IF(A28="","",IFERROR(INDEX(Table_Complete_CGNC_PCG!$E:$E,MATCH(L28,Table_Complete_CGNC_PCG!$I:$I,0)),"? Non mappe")) -> 5121 / 5124 | G28: =IF(A28="","",IFERROR(INDEX(Table_Complete_CGNC_PCG!$F:$F,MATCH(L28,Table_Complete_CGNC_PCG!$I:$I,0)),"Non trouve — ajouter dans la table")) -> Comptes en euros / Comptes en devises | H28: =IF(OR(A28="",C28="",C28=0),"",ROUND(C28/$C$2,2)) -> 88091.09 | I28: =IF(OR(A28="",D28="",D28=0),"",ROUND(D28/$C$2,2)) | K28: =IF(A28="","",IFERROR(IF(F28="? Non mappe","Compte non trouve - mapper manuellement",IF(AND(ISNUMBER(SEARCH("516",L28)),D28>0),"CAISSE CREDITRICE - anomalie a corriger",IF(IFERROR(INDEX(Table_Complete_CGNC_PCG!$D:$D,MATCH(L28,Table_Complete_CGNC_PCG!$I:$I,0)),"")="?","Retraitement requis - voir table","OK"))),"Erreur")) -> OK | L28: =LEFT(TEXT(A28,"0"),4) -> 5141
A29: 5161000 | B29: Caisses | C29: 60015.39 | F29: =IF(A29="","",IFERROR(INDEX(Table_Complete_CGNC_PCG!$E:$E,MATCH(L29,Table_Complete_CGNC_PCG!$I:$I,0)),"? Non mappe")) -> 530 | G29: =IF(A29="","",IFERROR(INDEX(Table_Complete_CGNC_PCG!$F:$F,MATCH(L29,Table_Complete_CGNC_PCG!$I:$I,0)),"Non trouve — ajouter dans la table")) -> Caisse | H29: =IF(OR(A29="",C29="",C29=0),"",ROUND(C29/$C$2,2)) -> 5556.98 | I29: =IF(OR(A29="",D29="",D29=0),"",ROUND(D29/$C$2,2)) | K29: =IF(A29="","",IFERROR(IF(F29="? Non mappe","Compte non trouve - mapper manuellement",IF(AND(ISNUMBER(SEARCH("516",L29)),D29>0),"CAISSE CREDITRICE - anomalie a corriger",IF(IFERROR(INDEX(Table_Complete_CGNC_PCG!$D:$D,MATCH(L29,Table_Complete_CGNC_PCG!$I:$I,0)),"")="?","Retraitement requis - voir table","OK"))),"Erreur")) -> OK | L29: =LEFT(TEXT(A29,"0"),4) -> 5161
A30: 6121100 | B30: Achats de matières premières A | C30: 93901.1 | F30: =IF(A30="","",IFERROR(INDEX(Table_Complete_CGNC_PCG!$E:$E,MATCH(L30,Table_Complete_CGNC_PCG!$I:$I,0)),"? Non mappe")) -> 601 | G30: =IF(A30="","",IFERROR(INDEX(Table_Complete_CGNC_PCG!$F:$F,MATCH(L30,Table_Complete_CGNC_PCG!$I:$I,0)),"Non trouve — ajouter dans la table")) -> Achats stockés - Matières premières et fournitures | H30: =IF(OR(A30="",C30="",C30=0),"",ROUND(C30/$C$2,2)) -> 8694.55 | I30: =IF(OR(A30="",D30="",D30=0),"",ROUND(D30/$C$2,2)) | K30: =IF(A30="","",IFERROR(IF(F30="? Non mappe","Compte non trouve - mapper manuellement",IF(AND(ISNUMBER(SEARCH("516",L30)),D30>0),"CAISSE CREDITRICE - anomalie a corriger",IF(IFERROR(INDEX(Table_Complete_CGNC_PCG!$D:$D,MATCH(L30,Table_Complete_CGNC_PCG!$I:$I,0)),"")="?","Retraitement requis - voir table","OK"))),"Erreur")) -> OK | L30: =LEFT(TEXT(A30,"0"),4) -> 6121
A31: 6122400 | B31: Achats de produits d'entretien | C31: 20595.42 | F31: =IF(A31="","",IFERROR(INDEX(Table_Complete_CGNC_PCG!$E:$E,MATCH(L31,Table_Complete_CGNC_PCG!$I:$I,0)),"? Non mappe")) -> 602 | G31: =IF(A31="","",IFERROR(INDEX(Table_Complete_CGNC_PCG!$F:$F,MATCH(L31,Table_Complete_CGNC_PCG!$I:$I,0)),"Non trouve — ajouter dans la table")) -> Achats stockés - Autres approvisionnements | H31: =IF(OR(A31="",C31="",C31=0),"",ROUND(C31/$C$2,2)) -> 1906.98 | I31: =IF(OR(A31="",D31="",D31=0),"",ROUND(D31/$C$2,2)) | K31: =IF(A31="","",IFERROR(IF(F31="? Non mappe","Compte non trouve - mapper manuellement",IF(AND(ISNUMBER(SEARCH("516",L31)),D31>0),"CAISSE CREDITRICE - anomalie a corriger",IF(IFERROR(INDEX(Table_Complete_CGNC_PCG!$D:$D,MATCH(L31,Table_Complete_CGNC_PCG!$I:$I,0)),"")="?","Retraitement requis - voir table","OK"))),"Erreur")) -> OK | L31: =LEFT(TEXT(A31,"0"),4) -> 6122
A32: 6125100 | B32: Achats de fournitures non stockables (eau, élec.) | C32: 9560.71 | F32: =IF(A32="","",IFERROR(INDEX(Table_Complete_CGNC_PCG!$E:$E,MATCH(L32,Table_Complete_CGNC_PCG!$I:$I,0)),"? Non mappe")) -> 6061 | G32: =IF(A32="","",IFERROR(INDEX(Table_Complete_CGNC_PCG!$F:$F,MATCH(L32,Table_Complete_CGNC_PCG!$I:$I,0)),"Non trouve — ajouter dans la table")) -> Fournitures non stockables (eau, énergie) | H32: =IF(OR(A32="",C32="",C32=0),"",ROUND(C32/$C$2,2)) -> 885.25 | I32: =IF(OR(A32="",D32="",D32=0),"",ROUND(D32/$C$2,2)) | K32: =IF(A32="","",IFERROR(IF(F32="? Non mappe","Compte non trouve - mapper manuellement",IF(AND(ISNUMBER(SEARCH("516",L32)),D32>0),"CAISSE CREDITRICE - anomalie a corriger",IF(IFERROR(INDEX(Table_Complete_CGNC_PCG!$D:$D,MATCH(L32,Table_Complete_CGNC_PCG!$I:$I,0)),"")="?","Retraitement requis - voir table","OK"))),"Erreur")) -> OK | L32: =LEFT(TEXT(A32,"0"),5) -> 61251
A33: 6125300 | B33: Achats de petit outillage et petit équipement | C33: 45528.66 | F33: =IF(A33="","",IFERROR(INDEX(Table_Complete_CGNC_PCG!$E:$E,MATCH(L33,Table_Complete_CGNC_PCG!$I:$I,0)),"? Non mappe")) -> 6063 | G33: =IF(A33="","",IFERROR(INDEX(Table_Complete_CGNC_PCG!$F:$F,MATCH(L33,Table_Complete_CGNC_PCG!$I:$I,0)),"Non trouve — ajouter dans la table")) -> Fournitures d'entretien et de petit équipement | H33: =IF(OR(A33="",C33="",C33=0),"",ROUND(C33/$C$2,2)) -> 4215.62 | I33: =IF(OR(A33="",D33="",D33=0),"",ROUND(D33/$C$2,2)) | K33: =IF(A33="","",IFERROR(IF(F33="? Non mappe","Compte non trouve - mapper manuellement",IF(AND(ISNUMBER(SEARCH("516",L33)),D33>0),"CAISSE CREDITRICE - anomalie a corriger",IF(IFERROR(INDEX(Table_Complete_CGNC_PCG!$D:$D,MATCH(L33,Table_Complete_CGNC_PCG!$I:$I,0)),"")="?","Retraitement requis - voir table","OK"))),"Erreur")) -> OK | L33: =LEFT(TEXT(A33,"0"),5) -> 61253
A34: 6133100 | B34: Entretien et réparations des biens immobiliers | C34: 46577.37 | F34: =IF(A34="","",IFERROR(INDEX(Table_Complete_CGNC_PCG!$E:$E,MATCH(L34,Table_Complete_CGNC_PCG!$I:$I,0)),"? Non mappe")) -> 6152 | G34: =IF(A34="","",IFERROR(INDEX(Table_Complete_CGNC_PCG!$F:$F,MATCH(L34,Table_Complete_CGNC_PCG!$I:$I,0)),"Non trouve — ajouter dans la table")) -> Entretien et réparation sur biens immobiliers | H34: =IF(OR(A34="",C34="",C34=0),"",ROUND(C34/$C$2,2)) -> 4312.72 | I34: =IF(OR(A34="",D34="",D34=0),"",ROUND(D34/$C$2,2)) | K34: =IF(A34="","",IFERROR(IF(F34="? Non mappe","Compte non trouve - mapper manuellement",IF(AND(ISNUMBER(SEARCH("516",L34)),D34>0),"CAISSE CREDITRICE - anomalie a corriger",IF(IFERROR(INDEX(Table_Complete_CGNC_PCG!$D:$D,MATCH(L34,Table_Complete_CGNC_PCG!$I:$I,0)),"")="?","Retraitement requis - voir table","OK"))),"Erreur")) -> OK | L34: =LEFT(TEXT(A34,"0"),5) -> 61331
A35: 6131200 | B35: Loyers Holding | C35: 114000 | F35: =IF(A35="","",IFERROR(INDEX(Table_Complete_CGNC_PCG!$E:$E,MATCH(L35,Table_Complete_CGNC_PCG!$I:$I,0)),"? Non mappe")) -> 6132 | G35: =IF(A35="","",IFERROR(INDEX(Table_Complete_CGNC_PCG!$F:$F,MATCH(L35,Table_Complete_CGNC_PCG!$I:$I,0)),"Non trouve — ajouter dans la table")) -> Locations immobilières | H35: =IF(OR(A35="",C35="",C35=0),"",ROUND(C35/$C$2,2)) -> 10555.56 | I35: =IF(OR(A35="",D35="",D35=0),"",ROUND(D35/$C$2,2)) | K35: =IF(A35="","",IFERROR(IF(F35="? Non mappe","Compte non trouve - mapper manuellement",IF(AND(ISNUMBER(SEARCH("516",L35)),D35>0),"CAISSE CREDITRICE - anomalie a corriger",IF(IFERROR(INDEX(Table_Complete_CGNC_PCG!$D:$D,MATCH(L35,Table_Complete_CGNC_PCG!$I:$I,0)),"")="?","Retraitement requis - voir table","OK"))),"Erreur")) -> OK | L35: =LEFT(TEXT(A35,"0"),5) -> 61312
A36: 6136500 | B36: Commissions plateformes | C36: 99388 | F36: =IF(A36="","",IFERROR(INDEX(Table_Complete_CGNC_PCG!$E:$E,MATCH(L36,Table_Complete_CGNC_PCG!$I:$I,0)),"? Non mappe")) -> 6226 | G36: =IF(A36="","",IFERROR(INDEX(Table_Complete_CGNC_PCG!$F:$F,MATCH(L36,Table_Complete_CGNC_PCG!$I:$I,0)),"Non trouve — ajouter dans la table")) -> Honoraires | H36: =IF(OR(A36="",C36="",C36=0),"",ROUND(C36/$C$2,2)) -> 9202.59 | I36: =IF(OR(A36="",D36="",D36=0),"",ROUND(D36/$C$2,2)) | K36: =IF(A36="","",IFERROR(IF(F36="? Non mappe","Compte non trouve - mapper manuellement",IF(AND(ISNUMBER(SEARCH("516",L36)),D36>0),"CAISSE CREDITRICE - anomalie a corriger",IF(IFERROR(INDEX(Table_Complete_CGNC_PCG!$D:$D,MATCH(L36,Table_Complete_CGNC_PCG!$I:$I,0)),"")="?","Retraitement requis - voir table","OK"))),"Erreur")) -> OK | L36: =LEFT(TEXT(A36,"0"),5) -> 61365
A37: 6136500 | B37: Honoraires divers | C37: 30605 | F37: =IF(A37="","",IFERROR(INDEX(Table_Complete_CGNC_PCG!$E:$E,MATCH(L37,Table_Complete_CGNC_PCG!$I:$I,0)),"? Non mappe")) -> 6226 | G37: =IF(A37="","",IFERROR(INDEX(Table_Complete_CGNC_PCG!$F:$F,MATCH(L37,Table_Complete_CGNC_PCG!$I:$I,0)),"Non trouve — ajouter dans la table")) -> Honoraires | H37: =IF(OR(A37="",C37="",C37=0),"",ROUND(C37/$C$2,2)) -> 2833.8 | I37: =IF(OR(A37="",D37="",D37=0),"",ROUND(D37/$C$2,2)) | K37: =IF(A37="","",IFERROR(IF(F37="? Non mappe","Compte non trouve - mapper manuellement",IF(AND(ISNUMBER(SEARCH("516",L37)),D37>0),"CAISSE CREDITRICE - anomalie a corriger",IF(IFERROR(INDEX(Table_Complete_CGNC_PCG!$D:$D,MATCH(L37,Table_Complete_CGNC_PCG!$I:$I,0)),"")="?","Retraitement requis - voir table","OK"))),"Erreur")) -> OK | L37: =LEFT(TEXT(A37,"0"),5) -> 61365
A38: 6141500 | B38: Documentation générale | C38: 4990 | F38: =IF(A38="","",IFERROR(INDEX(Table_Complete_CGNC_PCG!$E:$E,MATCH(L38,Table_Complete_CGNC_PCG!$I:$I,0)),"? Non mappe")) -> 6181 | G38: =IF(A38="","",IFERROR(INDEX(Table_Complete_CGNC_PCG!$F:$F,MATCH(L38,Table_Complete_CGNC_PCG!$I:$I,0)),"Non trouve — ajouter dans la table")) -> Documentation générale | H38: =IF(OR(A38="",C38="",C38=0),"",ROUND(C38/$C$2,2)) -> 462.04 | I38: =IF(OR(A38="",D38="",D38=0),"",ROUND(D38/$C$2,2)) | K38: =IF(A38="","",IFERROR(IF(F38="? Non mappe","Compte non trouve - mapper manuellement",IF(AND(ISNUMBER(SEARCH("516",L38)),D38>0),"CAISSE CREDITRICE - anomalie a corriger",IF(IFERROR(INDEX(Table_Complete_CGNC_PCG!$D:$D,MATCH(L38,Table_Complete_CGNC_PCG!$I:$I,0)),"")="?","Retraitement requis - voir table","OK"))),"Erreur")) -> OK | L38: =LEFT(TEXT(A38,"0"),5) -> 61415
A39: 6143100 | B39: Voyages et déplacements | C39: 32654.78 | F39: =IF(A39="","",IFERROR(INDEX(Table_Complete_CGNC_PCG!$E:$E,MATCH(L39,Table_Complete_CGNC_PCG!$I:$I,0)),"? Non mappe")) -> 6251 | G39: =IF(A39="","",IFERROR(INDEX(Table_Complete_CGNC_PCG!$F:$F,MATCH(L39,Table_Complete_CGNC_PCG!$I:$I,0)),"Non trouve — ajouter dans la table")) -> Voyages et déplacements | H39: =IF(OR(A39="",C39="",C39=0),"",ROUND(C39/$C$2,2)) -> 3023.59 | I39: =IF(OR(A39="",D39="",D39=0),"",ROUND(D39/$C$2,2)) | K39: =IF(A39="","",IFERROR(IF(F39="? Non mappe","Compte non trouve - mapper manuellement",IF(AND(ISNUMBER(SEARCH("516",L39)),D39>0),"CAISSE CREDITRICE - anomalie a corriger",IF(IFERROR(INDEX(Table_Complete_CGNC_PCG!$D:$D,MATCH(L39,Table_Complete_CGNC_PCG!$I:$I,0)),"")="?","Retraitement requis - voir table","OK"))),"Erreur")) -> OK | L39: =LEFT(TEXT(A39,"0"),5) -> 61431
A40: 6143600 | B40: Réceptions | C40: 20153.52 | F40: =IF(A40="","",IFERROR(INDEX(Table_Complete_CGNC_PCG!$E:$E,MATCH(L40,Table_Complete_CGNC_PCG!$I:$I,0)),"? Non mappe")) -> 6257 | G40: =IF(A40="","",IFERROR(INDEX(Table_Complete_CGNC_PCG!$F:$F,MATCH(L40,Table_Complete_CGNC_PCG!$I:$I,0)),"Non trouve — ajouter dans la table")) -> Réceptions | H40: =IF(OR(A40="",C40="",C40=0),"",ROUND(C40/$C$2,2)) -> 1866.07 | I40: =IF(OR(A40="",D40="",D40=0),"",ROUND(D40/$C$2,2)) | K40: =IF(A40="","",IFERROR(IF(F40="? Non mappe","Compte non trouve - mapper manuellement",IF(AND(ISNUMBER(SEARCH("516",L40)),D40>0),"CAISSE CREDITRICE - anomalie a corriger",IF(IFERROR(INDEX(Table_Complete_CGNC_PCG!$D:$D,MATCH(L40,Table_Complete_CGNC_PCG!$I:$I,0)),"")="?","Retraitement requis - voir table","OK"))),"Erreur")) -> OK | L40: =LEFT(TEXT(A40,"0"),5) -> 61436
...
