Workbook

Sheet Infos
B2: ÉTUDE FINANCIÈRE PRÉVISIONNELLE SUR 3 ANS EN MAD RIAD DU MÉMOIRE - Médina de Marrakech STRUCTURE : HOLDING + EXPLOITATION
B7: STRUCTURE JURIDIQUE RETENUE
B8: HOLDING MAROCAINE (SCI/SARL de gestion)
B9: Détient les murs du riad (actif immobilier)
B10: Emprunte 3 100 000 MAD auprès de la banque
B11: Loue le riad à la société d'exploitation
B12: Loyer = mensualité emprunt × 110%
B14: SARL D'EXPLOITATION (Monte Cristo / Riad Al Baraka)
B15: Exploite le riad (hébergement, restauration, spa…)
B16: Verse le loyer à la Holding chaque mois
B17: Encaisse le CA et paie les charges d'exploitation
B18: Résultat net soumis à l'IS Maroc (exo 5 ans possible)
B20: CHIFFRES CLÉS DU MONTAGE
B21: Coût total projet (Holding) | C21: 6,200,000 MAD
B22: Apport Holding (50%) | C22: 3,100,000 MAD
B23: Emprunt Holding 6% / 20 ans | C23: 3,100,000 MAD
B24: Mensualité emprunt | C24: 22 209 MAD/mois
B25: Loyer Holding --> Exploit. | C25: 24 430 MAD/mois (annuité ×110%)
B26: CA héberg. An1 (yield mgmt) | C26: 3 898 720 MAD
B27: Taux d'occ. moyen An1 | C27: 0.792
B29: ONGLETS
B30: ① Hypothèses Communes
B31: ② Holding CR Mensuel 3 ans
B32: ③ Exploitation CR Mensuel 3 ans
B33: ④ Exploitation Budget Trésorerie
B34: ⑤ Consolidé SIG & Rentabilité

Sheet ① Hypothèses
A1: HYPOTHÈSES COMMUNES RIAD DU MEMOIRE (MAD) HOLDING + EXPLOITATION
A3: BIEN IMMOBILIER (Holding)
A4: Prix d'acquisition du riad (MAD) | B4: 5500000 | C4: MAD | D4: Riad 8 ch. Médina Marrakech
A5: Frais d'acquisition (notaire + droits d'enregistrement etc.) | B5: 550000 | C5: MAD
A6: Travaux / rénovation | B6: 150000 | C6: MAD
A7: Coût total projet | B7: =B4+B5+B6 -> 6200000 | C7: MAD
A8: Taux de change EUR/MAD | B8: 10.8 | C8: EUR/MAD
A9: Coût total projet (EUR) | B9: =B7/B8 -> 574074.07 | C9: EUR
A11: FINANCEMENT HOLDING (emprunt bancaire marocain)
A12: Apport Holding (%) | B12: 0.5 | C12: % | D12: 50% minimum recommandé Maroc
A13: Apport Holding (MAD) | B13: =B7*B12 -> 3100000 | C13: MAD
A14: Montant emprunté (MAD) | B14: =B7-B13 -> 3100000 | C14: MAD
A15: Taux d'intérêt annuel | B15: 0.06 | C15: % | D15: Banque Populaire
A16: Durée du prêt (années) | B16: 20 | C16: ans
A17: Mensualité emprunt Holding | B17: =ROUND(B14*(B15/12)/(1-(1+B15/12)^(-B16*12)),0) -> 22209 | C17: MAD/mois
A18: Annuité emprunt Holding | B18: =B17*12 -> 266508 | C18: MAD/an
A19: Total remboursé sur 20 ans | B19: =B17*B16*12 -> 5330160 | C19: MAD
A20: Coût total du crédit | B20: =B19-B14 -> 2230160 | C20: MAD
A22: LOYER INTER-SOCIÉTÉS (Holding -> Exploitation)
A23: Marge de sécurité sur mensualité (%) | B23: 0.25 | C23: % | D23: Surplus couvre frais gestion Holding + sécurité
A24: Loyer mensuel HT (Exploit. → Holding) | B24: =ROUND(B17*(1+B23),0) -> 27761 | C24: MAD/mois
A25: Loyer annuel HT | B25: =B24*12 -> 333132 | C25: MAD/an
A26: Surplus annuel Holding (après annuité) | B26: =B25-B18 -> 66624 | C26: MAD/an
A28: YIELD MANAGEMENT & SAISONNALITÉ MARRAKECH (source : Outil 15)
A29: Nombre de chambres | B29: 8 | C29: chambres
A30: Prix Haute Saison (≥80% TO) | B30: 1500 | C30: MAD/nuit | D30: Benchmark riads Marrakech
A31: Prix Moyenne Saison (51-79%) | B31: 1200 | C31: MAD/nuit
A32: Prix Basse Saison (<=50%) | B32: 900 | C32: MAD/nuit
A34: TABLEAU SAISONNALITÉ Taux d'occupation & Prix Yield (Année 1)
A35: Mois | B35: TO Année 1 | C35: Saison | D35: Prix Yield (MAD/nuit)
A36: Janvier | B36: 0.5 | C36: =IF(B36>=0.8,"Haute Saison",IF(B36>=0.5,"Moyenne Saison","Basse Saison")) -> Moyenne Saison | D36: =IF(B36>=0.8,B30,IF(B36>=0.51,B31,B32)) -> 900
A37: Février | B37: 0.5 | C37: =IF(B37>=0.8,"Haute Saison",IF(B37>=0.5,"Moyenne Saison","Basse Saison")) -> Moyenne Saison | D37: =IF(B37>=0.8,B30,IF(B37>=0.51,B31,B32)) -> 900
A38: Mars | B38: 0.55 | C38: =IF(B38>=0.8,"Haute Saison",IF(B38>=0.5,"Moyenne Saison","Basse Saison")) -> Moyenne Saison | D38: =IF(B38>=0.8,B30,IF(B38>=0.51,B31,B32)) -> 1200
A39: Avril | B39: 0.65 | C39: =IF(B39>=0.8,"Haute Saison",IF(B39>=0.5,"Moyenne Saison","Basse Saison")) -> Moyenne Saison | D39: =IF(B39>=0.8,B30,IF(B39>=0.51,B31,B32)) -> 1200
A40: Mai | B40: 0.7 | C40: =IF(B40>=0.8,"Haute Saison",IF(B40>=0.5,"Moyenne Saison","Basse Saison")) -> Moyenne Saison | D40: =IF(B40>=0.8,B30,IF(B40>=0.51,B31,B32)) -> 1200
A41: Juin | B41: 0.85 | C41: =IF(B41>=0.8,"Haute Saison",IF(B41>=0.5,"Moyenne Saison","Basse Saison")) -> Haute Saison | D41: =IF(B41>=0.8,B30,IF(B41>=0.51,B31,B32)) -> 1500
A42: Juillet | B42: 1 | C42: =IF(B42>=0.8,"Haute Saison",IF(B42>=0.5,"Moyenne Saison","Basse Saison")) -> Haute Saison | D42: =IF(B42>=0.8,B30,IF(B42>=0.51,B31,B32)) -> 1500
A43: Août | B43: 1 | C43: =IF(B43>=0.8,"Haute Saison",IF(B43>=0.5,"Moyenne Saison","Basse Saison")) -> Haute Saison | D43: =IF(B43>=0.8,B30,IF(B43>=0.51,B31,B32)) -> 1500
A44: Septembre | B44: 1 | C44: =IF(B44>=0.8,"Haute Saison",IF(B44>=0.5,"Moyenne Saison","Basse Saison")) -> Haute Saison | D44: =IF(B44>=0.8,B30,IF(B44>=0.51,B31,B32)) -> 1500
A45: Octobre | B45: 0.8 | C45: =IF(B45>=0.8,"Haute Saison",IF(B45>=0.5,"Moyenne Saison","Basse Saison")) -> Haute Saison | D45: =IF(B45>=0.8,B30,IF(B45>=0.51,B31,B32)) -> 1500
...

Sheet ② Holding CR
A1: COMPTE DE RÉSULTAT PRÉVISIONNEL HOLDING RIAD DU MÉMOIRE (MAD HT)
A2: La Holding détient les murs. Elle perçoit le loyer de la SARL d'exploitation et rembourse l'emprunt bancaire. Son résultat est la différence loyer − annuité − amortissement.
C3: ANNÉE 1 2026 | Q3: ANNÉE 2 2027 | AE3: ANNÉE 3 2028
A4: LIBELLÉS | C4: Jan | D4: Fév | E4: Mar | F4: Avr | G4: Mai | H4: Juin | I4: Juil | J4: Août | K4: Sep | L4: Oct | M4: Nov | N4: Déc | O4: TOTAL | Q4: Jan | R4: Fév | S4: Mar | T4: Avr | U4: Mai | V4: Juin | W4: Juil | X4: Août | Y4: Sep | Z4: Oct | AA4: Nov | AB4: Déc | AC4: TOTAL | AE4: Jan | AF4: Fév | AG4: Mar | AH4: Avr | AI4: Mai | AJ4: Juin | AK4: Juil | AL4: Août | AM4: Sep | AN4: Oct | AO4: Nov | AP4: Déc | AQ4: TOTAL
A5: PRODUITS (loyers perçus de la SARL d'exploitation)
A6: Loyer perçu de la SARL d'exploitation | C6: ='① Hypothèses'!B24 -> 27761 | D6: ='① Hypothèses'!B24 -> 27761 | E6: ='① Hypothèses'!B24 -> 27761 | F6: ='① Hypothèses'!B24 -> 27761 | G6: ='① Hypothèses'!B24 -> 27761 | H6: ='① Hypothèses'!B24 -> 27761 | I6: ='① Hypothèses'!B24 -> 27761 | J6: ='① Hypothèses'!B24 -> 27761 | K6: ='① Hypothèses'!B24 -> 27761 | L6: ='① Hypothèses'!B24 -> 27761 | M6: ='① Hypothèses'!B24 -> 27761 | N6: ='① Hypothèses'!B24 -> 27761 | O6: =SUM(C6,D6,E6,F6,G6,H6,I6,J6,K6,L6,M6,N6) -> 333132 | Q6: ='① Hypothèses'!B24 -> 27761 | R6: ='① Hypothèses'!B24 -> 27761 | S6: ='① Hypothèses'!B24 -> 27761 | T6: ='① Hypothèses'!B24 -> 27761 | U6: ='① Hypothèses'!B24 -> 27761 | V6: ='① Hypothèses'!B24 -> 27761 | W6: ='① Hypothèses'!B24 -> 27761 | X6: ='① Hypothèses'!B24 -> 27761 | Y6: ='① Hypothèses'!B24 -> 27761 | Z6: ='① Hypothèses'!B24 -> 27761 | AA6: ='① Hypothèses'!B24 -> 27761 | AB6: ='① Hypothèses'!B24 -> 27761 | AC6: =SUM(Q6,R6,S6,T6,U6,V6,W6,X6,Y6,Z6,AA6,AB6) -> 333132 | AE6: ='① Hypothèses'!B24 -> 27761 | AF6: ='① Hypothèses'!B24 -> 27761 | AG6: ='① Hypothèses'!B24 -> 27761 | AH6: ='① Hypothèses'!B24 -> 27761 | AI6: ='① Hypothèses'!B24 -> 27761 | AJ6: ='① Hypothèses'!B24 -> 27761 | AK6: ='① Hypothèses'!B24 -> 27761 | AL6: ='① Hypothèses'!B24 -> 27761 | AM6: ='① Hypothèses'!B24 -> 27761 | AN6: ='① Hypothèses'!B24 -> 27761 | AO6: ='① Hypothèses'!B24 -> 27761 | AP6: ='① Hypothèses'!B24 -> 27761 | AQ6: =SUM(AE6,AF6,AG6,AH6,AI6,AJ6,AK6,AL6,AM6,AN6,AO6,AP6) -> 333132
A7: TOTAL PRODUITS HOLDING | C7: =C6 -> 27761 | D7: =D6 -> 27761 | E7: =E6 -> 27761 | F7: =F6 -> 27761 | G7: =G6 -> 27761 | H7: =H6 -> 27761 | I7: =I6 -> 27761 | J7: =J6 -> 27761 | ... N7: =N6 -> 27761 | O7: =SUM(C7,D7,E7,F7,G7,H7,I7,J7,K7,L7,M7,N7) -> 333132 | Q7: =Q6 -> 27761 | R7: =R6 -> 27761 | S7: =S6 -> 27761 | T7: =T6 -> 27761 | U7: =U6 -> 27761 | V7: =V6 -> 27761 | W7: =W6 -> 27761 | X7: =X6 -> 27761 | ... AB7: =AB6 -> 27761 | AC7: =SUM(Q7,R7,S7,T7,U7,V7,W7,X7,Y7,Z7,AA7,AB7) -> 333132 | AE7: =AE6 -> 27761 | AF7: =AF6 -> 27761 | AG7: =AG6 -> 27761 | AH7: =AH6 -> 27761 | AI7: =AI6 -> 27761 | AJ7: =AJ6 -> 27761 | AK7: =AK6 -> 27761 | AL7: =AL6 -> 27761 | ... AP7: =AP6 -> 27761 | AQ7: =SUM(AE7,AF7,AG7,AH7,AI7,AJ7,AK7,AL7,AM7,AN7,AO7,AP7) -> 333132
A8: CHARGES (remboursement emprunt + amortissements)
A9: Mensualité emprunt (capital + intérêts) | C9: ='① Hypothèses'!B17 -> 22209 | D9: ='① Hypothèses'!B17 -> 22209 | E9: ='① Hypothèses'!B17 -> 22209 | F9: ='① Hypothèses'!B17 -> 22209 | G9: ='① Hypothèses'!B17 -> 22209 | H9: ='① Hypothèses'!B17 -> 22209 | I9: ='① Hypothèses'!B17 -> 22209 | J9: ='① Hypothèses'!B17 -> 22209 | K9: ='① Hypothèses'!B17 -> 22209 | L9: ='① Hypothèses'!B17 -> 22209 | M9: ='① Hypothèses'!B17 -> 22209 | N9: ='① Hypothèses'!B17 -> 22209 | O9: =SUM(C9,D9,E9,F9,G9,H9,I9,J9,K9,L9,M9,N9) -> 266508 | Q9: ='① Hypothèses'!B17 -> 22209 | R9: ='① Hypothèses'!B17 -> 22209 | S9: ='① Hypothèses'!B17 -> 22209 | T9: ='① Hypothèses'!B17 -> 22209 | U9: ='① Hypothèses'!B17 -> 22209 | V9: ='① Hypothèses'!B17 -> 22209 | W9: ='① Hypothèses'!B17 -> 22209 | X9: ='① Hypothèses'!B17 -> 22209 | Y9: ='① Hypothèses'!B17 -> 22209 | Z9: ='① Hypothèses'!B17 -> 22209 | AA9: ='① Hypothèses'!B17 -> 22209 | AB9: ='① Hypothèses'!B17 -> 22209 | AC9: =SUM(Q9,R9,S9,T9,U9,V9,W9,X9,Y9,Z9,AA9,AB9) -> 266508 | AE9: ='① Hypothèses'!B17 -> 22209 | AF9: ='① Hypothèses'!B17 -> 22209 | AG9: ='① Hypothèses'!B17 -> 22209 | AH9: ='① Hypothèses'!B17 -> 22209 | AI9: ='① Hypothèses'!B17 -> 22209 | AJ9: ='① Hypothèses'!B17 -> 22209 | AK9: ='① Hypothèses'!B17 -> 22209 | AL9: ='① Hypothèses'!B17 -> 22209 | AM9: ='① Hypothèses'!B17 -> 22209 | AN9: ='① Hypothèses'!B17 -> 22209 | AO9: ='① Hypothèses'!B17 -> 22209 | AP9: ='① Hypothèses'!B17 -> 22209 | AQ9: =SUM(AE9,AF9,AG9,AH9,AI9,AJ9,AK9,AL9,AM9,AN9,AO9,AP9) -> 266508
A10: Frais de gestion Holding (assur., admin.) | C10: 3500 | D10: 3500 | E10: 3500 | F10: 3500 | G10: 3500 | H10: 3500 | I10: 3500 | J10: 3500 | K10: 3500 | L10: 3500 | M10: 3500 | N10: 3500 | O10: =SUM(C10,D10,E10,F10,G10,H10,I10,J10,K10,L10,M10,N10) -> 42000 | Q10: =3500*1.02 -> 3570 | R10: =3500*1.02 -> 3570 | S10: =3500*1.02 -> 3570 | T10: =3500*1.02 -> 3570 | U10: =3500*1.02 -> 3570 | V10: =3500*1.02 -> 3570 | W10: =3500*1.02 -> 3570 | X10: =3500*1.02 -> 3570 | ... AB10: =3500*1.02 -> 3570 | AC10: =SUM(Q10,R10,S10,T10,U10,V10,W10,X10,Y10,Z10,AA10,AB10) -> 42840 | AE10: =3500*1.04 -> 3640 | AF10: =3500*1.04 -> 3640 | AG10: =3500*1.04 -> 3640 | AH10: =3500*1.04 -> 3640 | AI10: =3500*1.04 -> 3640 | AJ10: =3500*1.04 -> 3640 | AK10: =3500*1.04 -> 3640 | AL10: =3500*1.04 -> 3640 | ... AP10: =3500*1.04 -> 3640 | AQ10: =SUM(AE10,AF10,AG10,AH10,AI10,AJ10,AK10,AL10,AM10,AN10,AO10,AP10) -> 43680
A11: Dotation aux amortissements (murs, gros œuvre) | C11: =ROUND('① Hypothèses'!B102/12,0) -> 25833 | D11: =ROUND('① Hypothèses'!B102/12,0) -> 25833 | E11: =ROUND('① Hypothèses'!B102/12,0) -> 25833 | F11: =ROUND('① Hypothèses'!B102/12,0) -> 25833 | G11: =ROUND('① Hypothèses'!B102/12,0) -> 25833 | H11: =ROUND('① Hypothèses'!B102/12,0) -> 25833 | I11: =ROUND('① Hypothèses'!B102/12,0) -> 25833 | J11: =ROUND('① Hypothèses'!B102/12,0) -> 25833 | K11: =ROUND('① Hypothèses'!B102/12,0) -> 25833 | L11: =ROUND('① Hypothèses'!B102/12,0) -> 25833 | M11: =ROUND('① Hypothèses'!B102/12,0) -> 25833 | N11: =ROUND('① Hypothèses'!B102/12,0) -> 25833 | O11: =SUM(C11,D11,E11,F11,G11,H11,I11,J11,K11,L11,M11,N11) -> 309996 | Q11: =ROUND('① Hypothèses'!B102/12,0) -> 25833 | R11: =ROUND('① Hypothèses'!B102/12,0) -> 25833 | S11: =ROUND('① Hypothèses'!B102/12,0) -> 25833 | T11: =ROUND('① Hypothèses'!B102/12,0) -> 25833 | U11: =ROUND('① Hypothèses'!B102/12,0) -> 25833 | V11: =ROUND('① Hypothèses'!B102/12,0) -> 25833 | W11: =ROUND('① Hypothèses'!B102/12,0) -> 25833 | X11: =ROUND('① Hypothèses'!B102/12,0) -> 25833 | Y11: =ROUND('① Hypothèses'!B102/12,0) -> 25833 | Z11: =ROUND('① Hypothèses'!B102/12,0) -> 25833 | AA11: =ROUND('① Hypothèses'!B102/12,0) -> 25833 | AB11: =ROUND('① Hypothèses'!B102/12,0) -> 25833 | AC11: =SUM(Q11,R11,S11,T11,U11,V11,W11,X11,Y11,Z11,AA11,AB11) -> 309996 | AE11: =ROUND('① Hypothèses'!B102/12,0) -> 25833 | AF11: =ROUND('① Hypothèses'!B102/12,0) -> 25833 | AG11: =ROUND('① Hypothèses'!B102/12,0) -> 25833 | AH11: =ROUND('① Hypothèses'!B102/12,0) -> 25833 | AI11: =ROUND('① Hypothèses'!B102/12,0) -> 25833 | AJ11: =ROUND('① Hypothèses'!B102/12,0) -> 25833 | AK11: =ROUND('① Hypothèses'!B102/12,0) -> 25833 | AL11: =ROUND('① Hypothèses'!B102/12,0) -> 25833 | AM11: =ROUND('① Hypothèses'!B102/12,0) -> 25833 | AN11: =ROUND('① Hypothèses'!B102/12,0) -> 25833 | AO11: =ROUND('① Hypothèses'!B102/12,0) -> 25833 | AP11: =ROUND('① Hypothèses'!B102/12,0) -> 25833 | AQ11: =SUM(AE11,AF11,AG11,AH11,AI11,AJ11,AK11,AL11,AM11,AN11,AO11,AP11) -> 309996
A12: TOTAL CHARGES HOLDING | C12: =C9+C10+C11 -> 51542 | D12: =D9+D10+D11 -> 51542 | E12: =E9+E10+E11 -> 51542 | F12: =F9+F10+F11 -> 51542 | G12: =G9+G10+G11 -> 51542 | H12: =H9+H10+H11 -> 51542 | I12: =I9+I10+I11 -> 51542 | J12: =J9+J10+J11 -> 51542 | ... N12: =N9+N10+N11 -> 51542 | O12: =SUM(C12,D12,E12,F12,G12,H12,I12,J12,K12,L12,M12,N12) -> 618504 | Q12: =Q9+Q10+Q11 -> 51612 | R12: =R9+R10+R11 -> 51612 | S12: =S9+S10+S11 -> 51612 | T12: =T9+T10+T11 -> 51612 | U12: =U9+U10+U11 -> 51612 | V12: =V9+V10+V11 -> 51612 | W12: =W9+W10+W11 -> 51612 | X12: =X9+X10+X11 -> 51612 | ... AB12: =AB9+AB10+AB11 -> 51612 | AC12: =SUM(Q12,R12,S12,T12,U12,V12,W12,X12,Y12,Z12,AA12,AB12) -> 619344 | AE12: =AE9+AE10+AE11 -> 51682 | AF12: =AF9+AF10+AF11 -> 51682 | AG12: =AG9+AG10+AG11 -> 51682 | AH12: =AH9+AH10+AH11 -> 51682 | AI12: =AI9+AI10+AI11 -> 51682 | AJ12: =AJ9+AJ10+AJ11 -> 51682 | AK12: =AK9+AK10+AK11 -> 51682 | AL12: =AL9+AL10+AL11 -> 51682 | ... AP12: =AP9+AP10+AP11 -> 51682 | AQ12: =SUM(AE12,AF12,AG12,AH12,AI12,AJ12,AK12,AL12,AM12,AN12,AO12,AP12) -> 620184
A13: RÉSULTATS
A14: Surplus trésorerie mensuel (loyer - mensualité) | C14: =C6-C9-C10 -> 2052 | D14: =D6-D9-D10 -> 2052 | E14: =E6-E9-E10 -> 2052 | F14: =F6-F9-F10 -> 2052 | G14: =G6-G9-G10 -> 2052 | H14: =H6-H9-H10 -> 2052 | I14: =I6-I9-I10 -> 2052 | J14: =J6-J9-J10 -> 2052 | ... N14: =N6-N9-N10 -> 2052 | O14: =SUM(C14,D14,E14,F14,G14,H14,I14,J14,K14,L14,M14,N14) -> 24624 | Q14: =Q6-Q9-Q10 -> 1982 | R14: =R6-R9-R10 -> 1982 | S14: =S6-S9-S10 -> 1982 | T14: =T6-T9-T10 -> 1982 | U14: =U6-U9-U10 -> 1982 | V14: =V6-V9-V10 -> 1982 | W14: =W6-W9-W10 -> 1982 | X14: =X6-X9-X10 -> 1982 | ... AB14: =AB6-AB9-AB10 -> 1982 | AC14: =SUM(Q14,R14,S14,T14,U14,V14,W14,X14,Y14,Z14,AA14,AB14) -> 23784 | AE14: =AE6-AE9-AE10 -> 1912 | AF14: =AF6-AF9-AF10 -> 1912 | AG14: =AG6-AG9-AG10 -> 1912 | AH14: =AH6-AH9-AH10 -> 1912 | AI14: =AI6-AI9-AI10 -> 1912 | AJ14: =AJ6-AJ9-AJ10 -> 1912 | AK14: =AK6-AK9-AK10 -> 1912 | AL14: =AL6-AL9-AL10 -> 1912 | ... AP14: =AP6-AP9-AP10 -> 1912 | AQ14: =SUM(AE14,AF14,AG14,AH14,AI14,AJ14,AK14,AL14,AM14,AN14,AO14,AP14) -> 22944
A15: RÉSULTAT NET HOLDING (avant IS) | C15: =C7-C12 -> -23781 | D15: =D7-D12 -> -23781 | E15: =E7-E12 -> -23781 | F15: =F7-F12 -> -23781 | G15: =G7-G12 -> -23781 | H15: =H7-H12 -> -23781 | I15: =I7-I12 -> -23781 | J15: =J7-J12 -> -23781 | ... N15: =N7-N12 -> -23781 | O15: =SUM(C15,D15,E15,F15,G15,H15,I15,J15,K15,L15,M15,N15) -> -285372 | Q15: =Q7-Q12 -> -23851 | R15: =R7-R12 -> -23851 | S15: =S7-S12 -> -23851 | T15: =T7-T12 -> -23851 | U15: =U7-U12 -> -23851 | V15: =V7-V12 -> -23851 | W15: =W7-W12 -> -23851 | X15: =X7-X12 -> -23851 | ... AB15: =AB7-AB12 -> -23851 | AC15: =SUM(Q15,R15,S15,T15,U15,V15,W15,X15,Y15,Z15,AA15,AB15) -> -286212 | AE15: =AE7-AE12 -> -23921 | AF15: =AF7-AF12 -> -23921 | AG15: =AG7-AG12 -> -23921 | AH15: =AH7-AH12 -> -23921 | AI15: =AI7-AI12 -> -23921 | AJ15: =AJ7-AJ12 -> -23921 | AK15: =AK7-AK12 -> -23921 | AL15: =AL7-AL12 -> -23921 | ... AP15: =AP7-AP12 -> -23921 | AQ15: =SUM(AE15,AF15,AG15,AH15,AI15,AJ15,AK15,AL15,AM15,AN15,AO15,AP15) -> -287052

Sheet ③ Exploitation CR
A1: COMPTE DE RÉSULTAT PRÉVISIONNEL EXPLOITATION (SARL) RIAD DU MEMOIRE (MAD HT)
C3: ANNÉE 1 2026 | Q3: ANNÉE 2 2027 | AE3: ANNÉE 3 2028
A4: LIBELLÉS | C4: Jan | D4: Fév | E4: Mar | F4: Avr | G4: Mai | H4: Juin | I4: Juil | J4: Août | K4: Sep | L4: Oct | M4: Nov | N4: Déc | O4: TOTAL | Q4: Jan | R4: Fév | S4: Mar | T4: Avr | U4: Mai | V4: Juin | W4: Juil | X4: Août | Y4: Sep | Z4: Oct | AA4: Nov | AB4: Déc | AC4: TOTAL | AE4: Jan | AF4: Fév | AG4: Mar | AH4: Avr | AI4: Mai | AJ4: Juin | AK4: Juil | AL4: Août | AM4: Sep | AN4: Oct | AO4: Nov | AP4: Déc | AQ4: TOTAL
A5: PRODUITS D'EXPLOITATION
A6: CA Hébergement (yield management) | C6: =ROUND('① Hypothèses'!B29*IF('① Hypothèses'!B36>=0.8,'① Hypothèses'!B30,IF('① Hypothèses'!B36>=0.51,'① Hypothèses'!B31,'① Hypothèses'!B32))*'① Hypothèses'!B36*31,0) -> 111600 | D6: =ROUND('① Hypothèses'!B29*IF('① Hypothèses'!B37>=0.8,'① Hypothèses'!B30,IF('① Hypothèses'!B37>=0.51,'① Hypothèses'!B31,'① Hypothèses'!B32))*'① Hypothèses'!B37*28,0) -> 100800 | E6: =ROUND('① Hypothèses'!B29*IF('① Hypothèses'!B38>=0.8,'① Hypothèses'!B30,IF('① Hypothèses'!B38>=0.51,'① Hypothèses'!B31,'① Hypothèses'!B32))*'① Hypothèses'!B38*31,0) -> 163680 | F6: =ROUND('① Hypothèses'!B29*IF('① Hypothèses'!B39>=0.8,'① Hypothèses'!B30,IF('① Hypothèses'!B39>=0.51,'① Hypothèses'!B31,'① Hypothèses'!B32))*'① Hypothèses'!B39*30,0) -> 187200 | G6: =ROUND('① Hypothèses'!B29*IF('① Hypothèses'!B40>=0.8,'① Hypothèses'!B30,IF('① Hypothèses'!B40>=0.51,'① Hypothèses'!B31,'① Hypothèses'!B32))*'① Hypothèses'!B40*31,0) -> 208320 | H6: =ROUND('① Hypothèses'!B29*IF('① Hypothèses'!B41>=0.8,'① Hypothèses'!B30,IF('① Hypothèses'!B41>=0.51,'① Hypothèses'!B31,'① Hypothèses'!B32))*'① Hypothèses'!B41*30,0) -> 306000 | I6: =ROUND('① Hypothèses'!B29*IF('① Hypothèses'!B42>=0.8,'① Hypothèses'!B30,IF('① Hypothèses'!B42>=0.51,'① Hypothèses'!B31,'① Hypothèses'!B32))*'① Hypothèses'!B42*31,0) -> 372000 | J6: =ROUND('① Hypothèses'!B29*IF('① Hypothèses'!B43>=0.8,'① Hypothèses'!B30,IF('① Hypothèses'!B43>=0.51,'① Hypothèses'!B31,'① Hypothèses'!B32))*'① Hypothèses'!B43*31,0) -> 372000 | K6: =ROUND('① Hypothèses'!B29*IF('① Hypothèses'!B44>=0.8,'① Hypothèses'!B30,IF('① Hypothèses'!B44>=0.51,'① Hypothèses'!B31,'① Hypothèses'!B32))*'① Hypothèses'!B44*30,0) -> 360000 | L6: =ROUND('① Hypothèses'!B29*IF('① Hypothèses'!B45>=0.8,'① Hypothèses'!B30,IF('① Hypothèses'!B45>=0.51,'① Hypothèses'!B31,'① Hypothèses'!B32))*'① Hypothèses'!B45*31,0) -> 297600 | M6: =ROUND('① Hypothèses'!B29*IF('① Hypothèses'!B46>=0.8,'① Hypothèses'!B30,IF('① Hypothèses'!B46>=0.51,'① Hypothèses'!B31,'① Hypothèses'!B32))*'① Hypothèses'!B46*30,0) -> 172800 | N6: =ROUND('① Hypothèses'!B29*IF('① Hypothèses'!B47>=0.8,'① Hypothèses'!B30,IF('① Hypothèses'!B47>=0.51,'① Hypothèses'!B31,'① Hypothèses'!B32))*'① Hypothèses'!B47*31,0) -> 193440 | O6: =SUM(C6,D6,E6,F6,G6,H6,I6,J6,K6,L6,M6,N6) -> 2845440 | Q6: =ROUND('① Hypothèses'!B29*IF(MIN(1,'① Hypothèses'!B36+'① Hypothèses'!B51)>=0.8,'① Hypothèses'!B30*(1+'① Hypothèses'!B53),IF(MIN(1,'① Hypothèses'!B36+'① Hypothèses'!B51)>=0.51,'① Hypothèses'!B31*(1+'① Hypothèses'!B53),'① Hypothèses'!B32*(1+'① Hypothèses'!B53)))*MIN(1,'① Hypothèses'!B36+'① Hypothèses'!B51)*31,0) -> 153294 | R6: =ROUND('① Hypothèses'!B29*IF(MIN(1,'① Hypothèses'!B37+'① Hypothèses'!B51)>=0.8,'① Hypothèses'!B30*(1+'① Hypothèses'!B53),IF(MIN(1,'① Hypothèses'!B37+'① Hypothèses'!B51)>=0.51,'① Hypothèses'!B31*(1+'① Hypothèses'!B53),'① Hypothèses'!B32*(1+'① Hypothèses'!B53)))*MIN(1,'① Hypothèses'!B37+'① Hypothèses'!B51)*28,0) -> 138459 | S6: =ROUND('① Hypothèses'!B29*IF(MIN(1,'① Hypothèses'!B38+'① Hypothèses'!B51)>=0.8,'① Hypothèses'!B30*(1+'① Hypothèses'!B53),IF(MIN(1,'① Hypothèses'!B38+'① Hypothèses'!B51)>=0.51,'① Hypothèses'!B31*(1+'① Hypothèses'!B53),'① Hypothèses'!B32*(1+'① Hypothèses'!B53)))*MIN(1,'① Hypothèses'!B38+'① Hypothèses'!B51)*31,0) -> 168323 | T6: =ROUND('① Hypothèses'!B29*IF(MIN(1,'① Hypothèses'!B39+'① Hypothèses'!B51)>=0.8,'① Hypothèses'!B30*(1+'① Hypothèses'!B53),IF(MIN(1,'① Hypothèses'!B39+'① Hypothèses'!B51)>=0.51,'① Hypothèses'!B31*(1+'① Hypothèses'!B53),'① Hypothèses'!B32*(1+'① Hypothèses'!B53)))*MIN(1,'① Hypothèses'!B39+'① Hypothèses'!B51)*30,0) -> 191981 | U6: =ROUND('① Hypothèses'!B29*IF(MIN(1,'① Hypothèses'!B40+'① Hypothèses'!B51)>=0.8,'① Hypothèses'!B30*(1+'① Hypothèses'!B53),IF(MIN(1,'① Hypothèses'!B40+'① Hypothèses'!B51)>=0.51,'① Hypothèses'!B31*(1+'① Hypothèses'!B53),'① Hypothèses'!B32*(1+'① Hypothèses'!B53)))*MIN(1,'① Hypothèses'!B40+'① Hypothèses'!B51)*31,0) -> 213409 | V6: =ROUND('① Hypothèses'!B29*IF(MIN(1,'① Hypothèses'!B41+'① Hypothèses'!B51)>=0.8,'① Hypothèses'!B30*(1+'① Hypothèses'!B53),IF(MIN(1,'① Hypothèses'!B41+'① Hypothèses'!B51)>=0.51,'① Hypothèses'!B31*(1+'① Hypothèses'!B53),'① Hypothèses'!B32*(1+'① Hypothèses'!B53)))*MIN(1,'① Hypothèses'!B41+'① Hypothèses'!B51)*30,0) -> 312696 | W6: =ROUND('① Hypothèses'!B29*IF(MIN(1,'① Hypothèses'!B42+'① Hypothèses'!B51)>=0.8,'① Hypothèses'!B30*(1+'① Hypothèses'!B53),IF(MIN(1,'① Hypothèses'!B42+'① Hypothèses'!B51)>=0.51,'① Hypothèses'!B31*(1+'① Hypothèses'!B53),'① Hypothèses'!B32*(1+'① Hypothèses'!B53)))*MIN(1,'① Hypothèses'!B42+'① Hypothèses'!B51)*31,0) -> 375720 | X6: =ROUND('① Hypothèses'!B29*IF(MIN(1,'① Hypothèses'!B43+'① Hypothèses'!B51)>=0.8,'① Hypothèses'!B30*(1+'① Hypothèses'!B53),IF(MIN(1,'① Hypothèses'!B43+'① Hypothèses'!B51)>=0.51,'① Hypothèses'!B31*(1+'① Hypothèses'!B53),'① Hypothèses'!B32*(1+'① Hypothèses'!B53)))*MIN(1,'① Hypothèses'!B43+'① Hypothèses'!B51)*31,0) -> 375720 | Y6: =ROUND('① Hypothèses'!B29*IF(MIN(1,'① Hypothèses'!B44+'① Hypothèses'!B51)>=0.8,'① Hypothèses'!B30*(1+'① Hypothèses'!B53),IF(MIN(1,'① Hypothèses'!B44+'① Hypothèses'!B51)>=0.51,'① Hypothèses'!B31*(1+'① Hypothèses'!B53),'① Hypothèses'!B32*(1+'① Hypothèses'!B53)))*MIN(1,'① Hypothèses'!B44+'① Hypothèses'!B51)*30,0) -> 363600 | Z6: =ROUND('① Hypothèses'!B29*IF(MIN(1,'① Hypothèses'!B45+'① Hypothèses'!B51)>=0.8,'① Hypothèses'!B30*(1+'① Hypothèses'!B53),IF(MIN(1,'① Hypothèses'!B45+'① Hypothèses'!B51)>=0.51,'① Hypothèses'!B31*(1+'① Hypothèses'!B53),'① Hypothèses'!B32*(1+'① Hypothèses'!B53)))*MIN(1,'① Hypothèses'!B45+'① Hypothèses'!B51)*31,0) -> 304333 | AA6: =ROUND('① Hypothèses'!B29*IF(MIN(1,'① Hypothèses'!B46+'① Hypothèses'!B51)>=0.8,'① Hypothèses'!B30*(1+'① Hypothèses'!B53),IF(MIN(1,'① Hypothèses'!B46+'① Hypothèses'!B51)>=0.51,'① Hypothèses'!B31*(1+'① Hypothèses'!B53),'① Hypothèses'!B32*(1+'① Hypothèses'!B53)))*MIN(1,'① Hypothèses'!B46+'① Hypothèses'!B51)*30,0) -> 177437 | AB6: =ROUND('① Hypothèses'!B29*IF(MIN(1,'① Hypothèses'!B47+'① Hypothèses'!B51)>=0.8,'① Hypothèses'!B30*(1+'① Hypothèses'!B53),IF(MIN(1,'① Hypothèses'!B47+'① Hypothèses'!B51)>=0.51,'① Hypothèses'!B31*(1+'① Hypothèses'!B53),'① Hypothèses'!B32*(1+'① Hypothèses'!B53)))*MIN(1,'① Hypothèses'!B47+'① Hypothèses'!B51)*31,0) -> 198380 | AC6: =SUM(Q6,R6,S6,T6,U6,V6,W6,X6,Y6,Z6,AA6,AB6) -> 2973352 | AE6: =ROUND('① Hypothèses'!B29*IF(MIN(1,'① Hypothèses'!B36+'① Hypothèses'!B52)>=0.8,'① Hypothèses'!B30*(1+'① Hypothèses'!B53)*(1+'① Hypothèses'!B54),IF(MIN(1,'① Hypothèses'!B36+'① Hypothèses'!B52)>=0.51,'① Hypothèses'!B31*(1+'① Hypothèses'!B53)*(1+'① Hypothèses'!B54),'① Hypothèses'!B32*(1+'① Hypothèses'!B53)*(1+'① Hypothèses'!B54)))*MIN(1,'① Hypothèses'!B36+'① Hypothèses'!B52)*31,0) -> 159426 | AF6: =ROUND('① Hypothèses'!B29*IF(MIN(1,'① Hypothèses'!B37+'① Hypothèses'!B52)>=0.8,'① Hypothèses'!B30*(1+'① Hypothèses'!B53)*(1+'① Hypothèses'!B54),IF(MIN(1,'① Hypothèses'!B37+'① Hypothèses'!B52)>=0.51,'① Hypothèses'!B31*(1+'① Hypothèses'!B53)*(1+'① Hypothèses'!B54),'① Hypothèses'!B32*(1+'① Hypothèses'!B53)*(1+'① Hypothèses'!B54)))*MIN(1,'① Hypothèses'!B37+'① Hypothèses'!B52)*28,0) -> 143997 | AG6: =ROUND('① Hypothèses'!B29*IF(MIN(1,'① Hypothèses'!B38+'① Hypothèses'!B52)>=0.8,'① Hypothèses'!B30*(1+'① Hypothèses'!B53)*(1+'① Hypothèses'!B54),IF(MIN(1,'① Hypothèses'!B38+'① Hypothèses'!B52)>=0.51,'① Hypothèses'!B31*(1+'① Hypothèses'!B53)*(1+'① Hypothèses'!B54),'① Hypothèses'!B32*(1+'① Hypothèses'!B53)*(1+'① Hypothèses'!B54)))*MIN(1,'① Hypothèses'!B38+'① Hypothèses'!B52)*31,0) -> 174755 | AH6: =ROUND('① Hypothèses'!B29*IF(MIN(1,'① Hypothèses'!B39+'① Hypothèses'!B52)>=0.8,'① Hypothèses'!B30*(1+'① Hypothèses'!B53)*(1+'① Hypothèses'!B54),IF(MIN(1,'① Hypothèses'!B39+'① Hypothèses'!B52)>=0.51,'① Hypothèses'!B31*(1+'① Hypothèses'!B53)*(1+'① Hypothèses'!B54),'① Hypothèses'!B32*(1+'① Hypothèses'!B53)*(1+'① Hypothèses'!B54)))*MIN(1,'① Hypothèses'!B39+'① Hypothèses'!B52)*30,0) -> 198787 | AI6: =ROUND('① Hypothèses'!B29*IF(MIN(1,'① Hypothèses'!B40+'① Hypothèses'!B52)>=0.8,'① Hypothèses'!B30*(1+'① Hypothèses'!B53)*(1+'① Hypothèses'!B54),IF(MIN(1,'① Hypothèses'!B40+'① Hypothèses'!B52)>=0.51,'① Hypothèses'!B31*(1+'① Hypothèses'!B53)*(1+'① Hypothèses'!B54),'① Hypothèses'!B32*(1+'① Hypothèses'!B53)*(1+'① Hypothèses'!B54)))*MIN(1,'① Hypothèses'!B40+'① Hypothèses'!B52)*31,0) -> 220743 | AJ6: =ROUND('① Hypothèses'!B29*IF(MIN(1,'① Hypothèses'!B41+'① Hypothèses'!B52)>=0.8,'① Hypothèses'!B30*(1+'① Hypothèses'!B53)*(1+'① Hypothèses'!B54),IF(MIN(1,'① Hypothèses'!B41+'① Hypothèses'!B52)>=0.51,'① Hypothèses'!B31*(1+'① Hypothèses'!B53)*(1+'① Hypothèses'!B54),'① Hypothèses'!B32*(1+'① Hypothèses'!B53)*(1+'① Hypothèses'!B54)))*MIN(1,'① Hypothèses'!B41+'① Hypothèses'!B52)*30,0) -> 322659 | AK6: =ROUND('① Hypothèses'!B29*IF(MIN(1,'① Hypothèses'!B42+'① Hypothèses'!B52)>=0.8,'① Hypothèses'!B30*(1+'① Hypothèses'!B53)*(1+'① Hypothèses'!B54),IF(MIN(1,'① Hypothèses'!B42+'① Hypothèses'!B52)>=0.51,'① Hypothèses'!B31*(1+'① Hypothèses'!B53)*(1+'① Hypothèses'!B54),'① Hypothèses'!B32*(1+'① Hypothèses'!B53)*(1+'① Hypothèses'!B54)))*MIN(1,'① Hypothèses'!B42+'① Hypothèses'!B52)*31,0) -> 383234 | AL6: =ROUND('① Hypothèses'!B29*IF(MIN(1,'① Hypothèses'!B43+'① Hypothèses'!B52)>=0.8,'① Hypothèses'!B30*(1+'① Hypothèses'!B53)*(1+'① Hypothèses'!B54),IF(MIN(1,'① Hypothèses'!B43+'① Hypothèses'!B52)>=0.51,'① Hypothèses'!B31*(1+'① Hypothèses'!B53)*(1+'① Hypothèses'!B54),'① Hypothèses'!B32*(1+'① Hypothèses'!B53)*(1+'① Hypothèses'!B54)))*MIN(1,'① Hypothèses'!B43+'① Hypothèses'!B52)*31,0) -> 383234 | AM6: =ROUND('① Hypothèses'!B29*IF(MIN(1,'① Hypothèses'!B44+'① Hypothèses'!B52)>=0.8,'① Hypothèses'!B30*(1+'① Hypothèses'!B53)*(1+'① Hypothèses'!B54),IF(MIN(1,'① Hypothèses'!B44+'① Hypothèses'!B52)>=0.51,'① Hypothèses'!B31*(1+'① Hypothèses'!B53)*(1+'① Hypothèses'!B54),'① Hypothèses'!B32*(1+'① Hypothèses'!B53)*(1+'① Hypothèses'!B54)))*MIN(1,'① Hypothèses'!B44+'① Hypothèses'!B52)*30,0) -> 370872 | AN6: =ROUND('① Hypothèses'!B29*IF(MIN(1,'① Hypothèses'!B45+'① Hypothèses'!B52)>=0.8,'① Hypothèses'!B30*(1+'① Hypothèses'!B53)*(1+'① Hypothèses'!B54),IF(MIN(1,'① Hypothèses'!B45+'① Hypothèses'!B52)>=0.51,'① Hypothèses'!B31*(1+'① Hypothèses'!B53)*(1+'① Hypothèses'!B54),'① Hypothèses'!B32*(1+'① Hypothèses'!B53)*(1+'① Hypothèses'!B54)))*MIN(1,'① Hypothèses'!B45+'① Hypothèses'!B52)*31,0) -> 314252 | AO6: =ROUND('① Hypothèses'!B29*IF(MIN(1,'① Hypothèses'!B46+'① Hypothèses'!B52)>=0.8,'① Hypothèses'!B30*(1+'① Hypothèses'!B53)*(1+'① Hypothèses'!B54),IF(MIN(1,'① Hypothèses'!B46+'① Hypothèses'!B52)>=0.51,'① Hypothèses'!B31*(1+'① Hypothèses'!B53)*(1+'① Hypothèses'!B54),'① Hypothèses'!B32*(1+'① Hypothèses'!B53)*(1+'① Hypothèses'!B54)))*MIN(1,'① Hypothèses'!B46+'① Hypothèses'!B52)*30,0) -> 183953 | AP6: =ROUND('① Hypothèses'!B29*IF(MIN(1,'① Hypothèses'!B47+'① Hypothèses'!B52)>=0.8,'① Hypothèses'!B30*(1+'① Hypothèses'!B53)*(1+'① Hypothèses'!B54),IF(MIN(1,'① Hypothèses'!B47+'① Hypothèses'!B52)>=0.51,'① Hypothèses'!B31*(1+'① Hypothèses'!B53)*(1+'① Hypothèses'!B54),'① Hypothèses'!B32*(1+'① Hypothèses'!B53)*(1+'① Hypothèses'!B54)))*MIN(1,'① Hypothèses'!B47+'① Hypothèses'!B52)*31,0) -> 205414 | AQ6: =SUM(AE6,AF6,AG6,AH6,AI6,AJ6,AK6,AL6,AM6,AN6,AO6,AP6) -> 3061326
A7: CA Restauration & petits-déjeuners | C7: =ROUND(C6*'① Hypothèses'!B59,0) -> 11160 | D7: =ROUND(D6*'① Hypothèses'!B59,0) -> 10080 | E7: =ROUND(E6*'① Hypothèses'!B59,0) -> 16368 | F7: =ROUND(F6*'① Hypothèses'!B59,0) -> 18720 | G7: =ROUND(G6*'① Hypothèses'!B59,0) -> 20832 | H7: =ROUND(H6*'① Hypothèses'!B59,0) -> 30600 | I7: =ROUND(I6*'① Hypothèses'!B59,0) -> 37200 | J7: =ROUND(J6*'① Hypothèses'!B59,0) -> 37200 | K7: =ROUND(K6*'① Hypothèses'!B59,0) -> 36000 | L7: =ROUND(L6*'① Hypothèses'!B59,0) -> 29760 | M7: =ROUND(M6*'① Hypothèses'!B59,0) -> 17280 | N7: =ROUND(N6*'① Hypothèses'!B59,0) -> 19344 | O7: =SUM(C7,D7,E7,F7,G7,H7,I7,J7,K7,L7,M7,N7) -> 284544 | Q7: =ROUND(Q6*'① Hypothèses'!B59,0) -> 15329 | R7: =ROUND(R6*'① Hypothèses'!B59,0) -> 13846 | S7: =ROUND(S6*'① Hypothèses'!B59,0) -> 16832 | T7: =ROUND(T6*'① Hypothèses'!B59,0) -> 19198 | U7: =ROUND(U6*'① Hypothèses'!B59,0) -> 21341 | V7: =ROUND(V6*'① Hypothèses'!B59,0) -> 31270 | W7: =ROUND(W6*'① Hypothèses'!B59,0) -> 37572 | X7: =ROUND(X6*'① Hypothèses'!B59,0) -> 37572 | Y7: =ROUND(Y6*'① Hypothèses'!B59,0) -> 36360 | Z7: =ROUND(Z6*'① Hypothèses'!B59,0) -> 30433 | AA7: =ROUND(AA6*'① Hypothèses'!B59,0) -> 17744 | AB7: =ROUND(AB6*'① Hypothèses'!B59,0) -> 19838 | AC7: =SUM(Q7,R7,S7,T7,U7,V7,W7,X7,Y7,Z7,AA7,AB7) -> 297335 | AE7: =ROUND(AE6*'① Hypothèses'!B59,0) -> 15943 | AF7: =ROUND(AF6*'① Hypothèses'!B59,0) -> 14400 | AG7: =ROUND(AG6*'① Hypothèses'!B59,0) -> 17476 | AH7: =ROUND(AH6*'① Hypothèses'!B59,0) -> 19879 | AI7: =ROUND(AI6*'① Hypothèses'!B59,0) -> 22074 | AJ7: =ROUND(AJ6*'① Hypothèses'!B59,0) -> 32266 | AK7: =ROUND(AK6*'① Hypothèses'!B59,0) -> 38323 | AL7: =ROUND(AL6*'① Hypothèses'!B59,0) -> 38323 | AM7: =ROUND(AM6*'① Hypothèses'!B59,0) -> 37087 | AN7: =ROUND(AN6*'① Hypothèses'!B59,0) -> 31425 | AO7: =ROUND(AO6*'① Hypothèses'!B59,0) -> 18395 | AP7: =ROUND(AP6*'① Hypothèses'!B59,0) -> 20541 | AQ7: =SUM(AE7,AF7,AG7,AH7,AI7,AJ7,AK7,AL7,AM7,AN7,AO7,AP7) -> 306132
A8: CA Spa & Hammam | C8: 0 | D8: 0 | E8: 0 | F8: 0 | G8: 0 | H8: 0 | I8: 0 | J8: 0 | K8: 0 | L8: 0 | M8: 0 | N8: 0 | O8: =SUM(C8,D8,E8,F8,G8,H8,I8,J8,K8,L8,M8,N8) -> 0 | Q8: =ROUND(Q6*'① Hypothèses'!B60,0) -> 15329 | R8: =ROUND(R6*'① Hypothèses'!B60,0) -> 13846 | S8: =ROUND(S6*'① Hypothèses'!B60,0) -> 16832 | T8: =ROUND(T6*'① Hypothèses'!B60,0) -> 19198 | U8: =ROUND(U6*'① Hypothèses'!B60,0) -> 21341 | V8: =ROUND(V6*'① Hypothèses'!B60,0) -> 31270 | W8: =ROUND(W6*'① Hypothèses'!B60,0) -> 37572 | X8: =ROUND(X6*'① Hypothèses'!B60,0) -> 37572 | Y8: =ROUND(Y6*'① Hypothèses'!B60,0) -> 36360 | Z8: =ROUND(Z6*'① Hypothèses'!B60,0) -> 30433 | AA8: =ROUND(AA6*'① Hypothèses'!B60,0) -> 17744 | AB8: =ROUND(AB6*'① Hypothèses'!B60,0) -> 19838 | AC8: =SUM(Q8,R8,S8,T8,U8,V8,W8,X8,Y8,Z8,AA8,AB8) -> 297335 | AE8: =ROUND(AE6*'① Hypothèses'!B60,0) -> 15943 | AF8: =ROUND(AF6*'① Hypothèses'!B60,0) -> 14400 | AG8: =ROUND(AG6*'① Hypothèses'!B60,0) -> 17476 | AH8: =ROUND(AH6*'① Hypothèses'!B60,0) -> 19879 | AI8: =ROUND(AI6*'① Hypothèses'!B60,0) -> 22074 | AJ8: =ROUND(AJ6*'① Hypothèses'!B60,0) -> 32266 | AK8: =ROUND(AK6*'① Hypothèses'!B60,0) -> 38323 | AL8: =ROUND(AL6*'① Hypothèses'!B60,0) -> 38323 | AM8: =ROUND(AM6*'① Hypothèses'!B60,0) -> 37087 | AN8: =ROUND(AN6*'① Hypothèses'!B60,0) -> 31425 | AO8: =ROUND(AO6*'① Hypothèses'!B60,0) -> 18395 | AP8: =ROUND(AP6*'① Hypothèses'!B60,0) -> 20541 | AQ8: =SUM(AE8,AF8,AG8,AH8,AI8,AJ8,AK8,AL8,AM8,AN8,AO8,AP8) -> 306132
A9: CA Activités & Excursions | C9: 0 | D9: 0 | E9: 0 | F9: 0 | G9: 0 | H9: 0 | O9: =SUM(C9,D9,E9,F9,G9,H9,I9,J9,K9,L9,M9,N9) -> 0 | Q9: =ROUND(Q6*'① Hypothèses'!B61,0) -> 22994 | R9: =ROUND(R6*'① Hypothèses'!B61,0) -> 20769 | S9: =ROUND(S6*'① Hypothèses'!B61,0) -> 25248 | T9: =ROUND(T6*'① Hypothèses'!B61,0) -> 28797 | U9: =ROUND(U6*'① Hypothèses'!B61,0) -> 32011 | V9: =ROUND(V6*'① Hypothèses'!B61,0) -> 46904 | W9: =ROUND(W6*'① Hypothèses'!B61,0) -> 56358 | X9: =ROUND(X6*'① Hypothèses'!B61,0) -> 56358 | Y9: =ROUND(Y6*'① Hypothèses'!B61,0) -> 54540 | Z9: =ROUND(Z6*'① Hypothèses'!B61,0) -> 45650 | AA9: =ROUND(AA6*'① Hypothèses'!B61,0) -> 26616 | AB9: =ROUND(AB6*'① Hypothèses'!B61,0) -> 29757 | AC9: =SUM(Q9,R9,S9,T9,U9,V9,W9,X9,Y9,Z9,AA9,AB9) -> 446002 | AE9: =ROUND(AE6*'① Hypothèses'!B61,0) -> 23914 | AF9: =ROUND(AF6*'① Hypothèses'!B61,0) -> 21600 | AG9: =ROUND(AG6*'① Hypothèses'!B61,0) -> 26213 | AH9: =ROUND(AH6*'① Hypothèses'!B61,0) -> 29818 | AI9: =ROUND(AI6*'① Hypothèses'!B61,0) -> 33111 | AJ9: =ROUND(AJ6*'① Hypothèses'!B61,0) -> 48399 | AK9: =ROUND(AK6*'① Hypothèses'!B61,0) -> 57485 | AL9: =ROUND(AL6*'① Hypothèses'!B61,0) -> 57485 | AM9: =ROUND(AM6*'① Hypothèses'!B61,0) -> 55631 | AN9: =ROUND(AN6*'① Hypothèses'!B61,0) -> 47138 | AO9: =ROUND(AO6*'① Hypothèses'!B61,0) -> 27593 | AP9: =ROUND(AP6*'① Hypothèses'!B61,0) -> 30812 | AQ9: =SUM(AE9,AF9,AG9,AH9,AI9,AJ9,AK9,AL9,AM9,AN9,AO9,AP9) -> 459199
A10: CA Séminaires & Événements [supprimé] | C10: 0 | D10: 0 | E10: 0 | F10: 0 | G10: 0 | H10: 0 | I10: 0 | J10: 0 | K10: 0 | L10: 0 | M10: 0 | N10: 0 | O10: 0 | Q10: 0 | R10: 0 | S10: 0 | T10: 0 | U10: 0 | V10: 0 | W10: 0 | X10: 0 | Y10: 0 | Z10: 0 | AA10: 0 | AB10: 0 | AC10: 0 | AE10: 0 | AF10: 0 | AG10: 0 | AH10: 0 | AI10: 0 | AJ10: 0 | AK10: 0 | AL10: 0 | AM10: 0 | AN10: 0 | AO10: 0 | AP10: 0 | AQ10: 0
A11: TOTAL PRODUITS D'EXPLOITATION | C11: =C6+C7+C8+C9+C10 -> 122760 | D11: =D6+D7+D8+D9+D10 -> 110880 | E11: =E6+E7+E8+E9+E10 -> 180048 | F11: =F6+F7+F8+F9+F10 -> 205920 | G11: =G6+G7+G8+G9+G10 -> 229152 | H11: =H6+H7+H8+H9+H10 -> 336600 | I11: =I6+I7+I8+I9+I10 -> 409200 | J11: =J6+J7+J8+J9+J10 -> 409200 | ... N11: =N6+N7+N8+N9+N10 -> 212784 | O11: =SUM(C11,D11,E11,F11,G11,H11,I11,J11,K11,L11,M11,N11) -> 3129984 | Q11: =Q6+Q7+Q8+Q9+Q10 -> 206946 | R11: =R6+R7+R8+R9+R10 -> 186920 | S11: =S6+S7+S8+S9+S10 -> 227235 | T11: =T6+T7+T8+T9+T10 -> 259174 | U11: =U6+U7+U8+U9+U10 -> 288102 | V11: =V6+V7+V8+V9+V10 -> 422140 | W11: =W6+W7+W8+W9+W10 -> 507222 | X11: =X6+X7+X8+X9+X10 -> 507222 | ... AB11: =AB6+AB7+AB8+AB9+AB10 -> 267813 | AC11: =SUM(Q11,R11,S11,T11,U11,V11,W11,X11,Y11,Z11,AA11,AB11) -> 4014024 | AE11: =AE6+AE7+AE8+AE9+AE10 -> 215226 | AF11: =AF6+AF7+AF8+AF9+AF10 -> 194397 | AG11: =AG6+AG7+AG8+AG9+AG10 -> 235920 | AH11: =AH6+AH7+AH8+AH9+AH10 -> 268363 | AI11: =AI6+AI7+AI8+AI9+AI10 -> 298002 | AJ11: =AJ6+AJ7+AJ8+AJ9+AJ10 -> 435590 | AK11: =AK6+AK7+AK8+AK9+AK10 -> 517365 | AL11: =AL6+AL7+AL8+AL9+AL10 -> 517365 | ... AP11: =AP6+AP7+AP8+AP9+AP10 -> 277308 | AQ11: =SUM(AE11,AF11,AG11,AH11,AI11,AJ11,AK11,AL11,AM11,AN11,AO11,AP11) -> 4132789
A12: CHARGES D'EXPLOITATION
A13: Commissions OTA (Booking, Airbnb) | C13: =ROUND(C6*'① Hypothèses'!B64,0) -> 17856 | D13: =ROUND(D6*'① Hypothèses'!B64,0) -> 16128 | E13: =ROUND(E6*'① Hypothèses'!B64,0) -> 26189 | F13: =ROUND(F6*'① Hypothèses'!B64,0) -> 29952 | G13: =ROUND(G6*'① Hypothèses'!B64,0) -> 33331 | H13: =ROUND(H6*'① Hypothèses'!B64,0) -> 48960 | I13: =ROUND(I6*'① Hypothèses'!B64,0) -> 59520 | J13: =ROUND(J6*'① Hypothèses'!B64,0) -> 59520 | K13: =ROUND(K6*'① Hypothèses'!B64,0) -> 57600 | L13: =ROUND(L6*'① Hypothèses'!B64,0) -> 47616 | M13: =ROUND(M6*'① Hypothèses'!B64,0) -> 27648 | N13: =ROUND(N6*'① Hypothèses'!B64,0) -> 30950 | O13: =SUM(C13,D13,E13,F13,G13,H13,I13,J13,K13,L13,M13,N13) -> 455270 | Q13: =ROUND(Q6*'① Hypothèses'!B64,0) -> 24527 | R13: =ROUND(R6*'① Hypothèses'!B64,0) -> 22153 | S13: =ROUND(S6*'① Hypothèses'!B64,0) -> 26932 | T13: =ROUND(T6*'① Hypothèses'!B64,0) -> 30717 | U13: =ROUND(U6*'① Hypothèses'!B64,0) -> 34145 | V13: =ROUND(V6*'① Hypothèses'!B64,0) -> 50031 | W13: =ROUND(W6*'① Hypothèses'!B64,0) -> 60115 | X13: =ROUND(X6*'① Hypothèses'!B64,0) -> 60115 | Y13: =ROUND(Y6*'① Hypothèses'!B64,0) -> 58176 | Z13: =ROUND(Z6*'① Hypothèses'!B64,0) -> 48693 | AA13: =ROUND(AA6*'① Hypothèses'!B64,0) -> 28390 | AB13: =ROUND(AB6*'① Hypothèses'!B64,0) -> 31741 | AC13: =SUM(Q13,R13,S13,T13,U13,V13,W13,X13,Y13,Z13,AA13,AB13) -> 475735 | AE13: =ROUND(AE6*'① Hypothèses'!B64,0) -> 25508 | AF13: =ROUND(AF6*'① Hypothèses'!B64,0) -> 23040 | AG13: =ROUND(AG6*'① Hypothèses'!B64,0) -> 27961 | AH13: =ROUND(AH6*'① Hypothèses'!B64,0) -> 31806 | AI13: =ROUND(AI6*'① Hypothèses'!B64,0) -> 35319 | AJ13: =ROUND(AJ6*'① Hypothèses'!B64,0) -> 51625 | AK13: =ROUND(AK6*'① Hypothèses'!B64,0) -> 61317 | AL13: =ROUND(AL6*'① Hypothèses'!B64,0) -> 61317 | AM13: =ROUND(AM6*'① Hypothèses'!B64,0) -> 59340 | AN13: =ROUND(AN6*'① Hypothèses'!B64,0) -> 50280 | AO13: =ROUND(AO6*'① Hypothèses'!B64,0) -> 29432 | AP13: =ROUND(AP6*'① Hypothèses'!B64,0) -> 32866 | AQ13: =SUM(AE13,AF13,AG13,AH13,AI13,AJ13,AK13,AL13,AM13,AN13,AO13,AP13) -> 489811
A14: Achats marchandises restauration | C14: =ROUND(C7*'① Hypothèses'!B65,0) -> 4464 | D14: =ROUND(D7*'① Hypothèses'!B65,0) -> 4032 | E14: =ROUND(E7*'① Hypothèses'!B65,0) -> 6547 | F14: =ROUND(F7*'① Hypothèses'!B65,0) -> 7488 | G14: =ROUND(G7*'① Hypothèses'!B65,0) -> 8333 | H14: =ROUND(H7*'① Hypothèses'!B65,0) -> 12240 | I14: =ROUND(I7*'① Hypothèses'!B65,0) -> 14880 | J14: =ROUND(J7*'① Hypothèses'!B65,0) -> 14880 | K14: =ROUND(K7*'① Hypothèses'!B65,0) -> 14400 | L14: =ROUND(L7*'① Hypothèses'!B65,0) -> 11904 | M14: =ROUND(M7*'① Hypothèses'!B65,0) -> 6912 | N14: =ROUND(N7*'① Hypothèses'!B65,0) -> 7738 | O14: =SUM(C14,D14,E14,F14,G14,H14,I14,J14,K14,L14,M14,N14) -> 113818 | Q14: =ROUND(Q7*'① Hypothèses'!B65,0) -> 6132 | R14: =ROUND(R7*'① Hypothèses'!B65,0) -> 5538 | S14: =ROUND(S7*'① Hypothèses'!B65,0) -> 6733 | T14: =ROUND(T7*'① Hypothèses'!B65,0) -> 7679 | U14: =ROUND(U7*'① Hypothèses'!B65,0) -> 8536 | V14: =ROUND(V7*'① Hypothèses'!B65,0) -> 12508 | W14: =ROUND(W7*'① Hypothèses'!B65,0) -> 15029 | X14: =ROUND(X7*'① Hypothèses'!B65,0) -> 15029 | Y14: =ROUND(Y7*'① Hypothèses'!B65,0) -> 14544 | Z14: =ROUND(Z7*'① Hypothèses'!B65,0) -> 12173 | AA14: =ROUND(AA7*'① Hypothèses'!B65,0) -> 7098 | AB14: =ROUND(AB7*'① Hypothèses'!B65,0) -> 7935 | AC14: =SUM(Q14,R14,S14,T14,U14,V14,W14,X14,Y14,Z14,AA14,AB14) -> 118934 | AE14: =ROUND(AE7*'① Hypothèses'!B65,0) -> 6377 | AF14: =ROUND(AF7*'① Hypothèses'!B65,0) -> 5760 | AG14: =ROUND(AG7*'① Hypothèses'!B65,0) -> 6990 | AH14: =ROUND(AH7*'① Hypothèses'!B65,0) -> 7952 | AI14: =ROUND(AI7*'① Hypothèses'!B65,0) -> 8830 | AJ14: =ROUND(AJ7*'① Hypothèses'!B65,0) -> 12906 | AK14: =ROUND(AK7*'① Hypothèses'!B65,0) -> 15329 | AL14: =ROUND(AL7*'① Hypothèses'!B65,0) -> 15329 | AM14: =ROUND(AM7*'① Hypothèses'!B65,0) -> 14835 | AN14: =ROUND(AN7*'① Hypothèses'!B65,0) -> 12570 | AO14: =ROUND(AO7*'① Hypothèses'!B65,0) -> 7358 | AP14: =ROUND(AP7*'① Hypothèses'!B65,0) -> 8216 | AQ14: =SUM(AE14,AF14,AG14,AH14,AI14,AJ14,AK14,AL14,AM14,AN14,AO14,AP14) -> 122452
A15: Loyer versé à la Holding (bail commercial) | C15: ='① Hypothèses'!B24 -> 27761 | D15: ='① Hypothèses'!B24 -> 27761 | E15: ='① Hypothèses'!B24 -> 27761 | F15: ='① Hypothèses'!B24 -> 27761 | G15: ='① Hypothèses'!B24 -> 27761 | H15: ='① Hypothèses'!B24 -> 27761 | I15: ='① Hypothèses'!B24 -> 27761 | J15: ='① Hypothèses'!B24 -> 27761 | K15: ='① Hypothèses'!B24 -> 27761 | L15: ='① Hypothèses'!B24 -> 27761 | M15: ='① Hypothèses'!B24 -> 27761 | N15: ='① Hypothèses'!B24 -> 27761 | O15: =SUM(C15,D15,E15,F15,G15,H15,I15,J15,K15,L15,M15,N15) -> 333132 | Q15: ='① Hypothèses'!B24 -> 27761 | R15: ='① Hypothèses'!B24 -> 27761 | S15: ='① Hypothèses'!B24 -> 27761 | T15: ='① Hypothèses'!B24 -> 27761 | U15: ='① Hypothèses'!B24 -> 27761 | V15: ='① Hypothèses'!B24 -> 27761 | W15: ='① Hypothèses'!B24 -> 27761 | X15: ='① Hypothèses'!B24 -> 27761 | Y15: ='① Hypothèses'!B24 -> 27761 | Z15: ='① Hypothèses'!B24 -> 27761 | AA15: ='① Hypothèses'!B24 -> 27761 | AB15: ='① Hypothèses'!B24 -> 27761 | AC15: =SUM(Q15,R15,S15,T15,U15,V15,W15,X15,Y15,Z15,AA15,AB15) -> 333132 | AE15: ='① Hypothèses'!B24 -> 27761 | AF15: ='① Hypothèses'!B24 -> 27761 | AG15: ='① Hypothèses'!B24 -> 27761 | AH15: ='① Hypothèses'!B24 -> 27761 | AI15: ='① Hypothèses'!B24 -> 27761 | AJ15: ='① Hypothèses'!B24 -> 27761 | AK15: ='① Hypothèses'!B24 -> 27761 | AL15: ='① Hypothèses'!B24 -> 27761 | AM15: ='① Hypothèses'!B24 -> 27761 | AN15: ='① Hypothèses'!B24 -> 27761 | AO15: ='① Hypothèses'!B24 -> 27761 | AP15: ='① Hypothèses'!B24 -> 27761 | AQ15: =SUM(AE15,AF15,AG15,AH15,AI15,AJ15,AK15,AL15,AM15,AN15,AO15,AP15) -> 333132
A16: Assurances | C16: =ROUND('① Hypothèses'!B66/12,0) -> 3750 | D16: =ROUND('① Hypothèses'!B66/12,0) -> 3750 | E16: =ROUND('① Hypothèses'!B66/12,0) -> 3750 | F16: =ROUND('① Hypothèses'!B66/12,0) -> 3750 | G16: =ROUND('① Hypothèses'!B66/12,0) -> 3750 | H16: =ROUND('① Hypothèses'!B66/12,0) -> 3750 | I16: =ROUND('① Hypothèses'!B66/12,0) -> 3750 | J16: =ROUND('① Hypothèses'!B66/12,0) -> 3750 | K16: =ROUND('① Hypothèses'!B66/12,0) -> 3750 | L16: =ROUND('① Hypothèses'!B66/12,0) -> 3750 | M16: =ROUND('① Hypothèses'!B66/12,0) -> 3750 | N16: =ROUND('① Hypothèses'!B66/12,0) -> 3750 | O16: =SUM(C16,D16,E16,F16,G16,H16,I16,J16,K16,L16,M16,N16) -> 45000 | Q16: =ROUND('① Hypothèses'!B66/12*(1+'① Hypothèses'!B55),0) -> 3825 | R16: =ROUND('① Hypothèses'!B66/12*(1+'① Hypothèses'!B55),0) -> 3825 | S16: =ROUND('① Hypothèses'!B66/12*(1+'① Hypothèses'!B55),0) -> 3825 | T16: =ROUND('① Hypothèses'!B66/12*(1+'① Hypothèses'!B55),0) -> 3825 | U16: =ROUND('① Hypothèses'!B66/12*(1+'① Hypothèses'!B55),0) -> 3825 | V16: =ROUND('① Hypothèses'!B66/12*(1+'① Hypothèses'!B55),0) -> 3825 | W16: =ROUND('① Hypothèses'!B66/12*(1+'① Hypothèses'!B55),0) -> 3825 | X16: =ROUND('① Hypothèses'!B66/12*(1+'① Hypothèses'!B55),0) -> 3825 | Y16: =ROUND('① Hypothèses'!B66/12*(1+'① Hypothèses'!B55),0) -> 3825 | Z16: =ROUND('① Hypothèses'!B66/12*(1+'① Hypothèses'!B55),0) -> 3825 | AA16: =ROUND('① Hypothèses'!B66/12*(1+'① Hypothèses'!B55),0) -> 3825 | AB16: =ROUND('① Hypothèses'!B66/12*(1+'① Hypothèses'!B55),0) -> 3825 | AC16: =SUM(Q16,R16,S16,T16,U16,V16,W16,X16,Y16,Z16,AA16,AB16) -> 45900 | AE16: =ROUND('① Hypothèses'!B66/12*(1+'① Hypothèses'!B55)^2,0) -> 3902 | AF16: =ROUND('① Hypothèses'!B66/12*(1+'① Hypothèses'!B55)^2,0) -> 3902 | AG16: =ROUND('① Hypothèses'!B66/12*(1+'① Hypothèses'!B55)^2,0) -> 3902 | AH16: =ROUND('① Hypothèses'!B66/12*(1+'① Hypothèses'!B55)^2,0) -> 3902 | AI16: =ROUND('① Hypothèses'!B66/12*(1+'① Hypothèses'!B55)^2,0) -> 3902 | AJ16: =ROUND('① Hypothèses'!B66/12*(1+'① Hypothèses'!B55)^2,0) -> 3902 | AK16: =ROUND('① Hypothèses'!B66/12*(1+'① Hypothèses'!B55)^2,0) -> 3902 | AL16: =ROUND('① Hypothèses'!B66/12*(1+'① Hypothèses'!B55)^2,0) -> 3902 | AM16: =ROUND('① Hypothèses'!B66/12*(1+'① Hypothèses'!B55)^2,0) -> 3902 | AN16: =ROUND('① Hypothèses'!B66/12*(1+'① Hypothèses'!B55)^2,0) -> 3902 | AO16: =ROUND('① Hypothèses'!B66/12*(1+'① Hypothèses'!B55)^2,0) -> 3902 | AP16: =ROUND('① Hypothèses'!B66/12*(1+'① Hypothèses'!B55)^2,0) -> 3902 | AQ16: =SUM(AE16,AF16,AG16,AH16,AI16,AJ16,AK16,AL16,AM16,AN16,AO16,AP16) -> 46824
A17: Eau, électricité, gaz | C17: =ROUND('① Hypothèses'!B67,0) -> 15000 | D17: =ROUND('① Hypothèses'!B67,0) -> 15000 | E17: =ROUND('① Hypothèses'!B67,0) -> 15000 | F17: =ROUND('① Hypothèses'!B67,0) -> 15000 | G17: =ROUND('① Hypothèses'!B67,0) -> 15000 | H17: =ROUND('① Hypothèses'!B67,0) -> 15000 | I17: =ROUND('① Hypothèses'!B67,0) -> 15000 | J17: =ROUND('① Hypothèses'!B67,0) -> 15000 | K17: =ROUND('① Hypothèses'!B67,0) -> 15000 | L17: =ROUND('① Hypothèses'!B67,0) -> 15000 | M17: =ROUND('① Hypothèses'!B67,0) -> 15000 | N17: =ROUND('① Hypothèses'!B67,0) -> 15000 | O17: =SUM(C17,D17,E17,F17,G17,H17,I17,J17,K17,L17,M17,N17) -> 180000 | Q17: =ROUND('① Hypothèses'!B67*(1+'① Hypothèses'!B55),0) -> 15300 | R17: =ROUND('① Hypothèses'!B67*(1+'① Hypothèses'!B55),0) -> 15300 | S17: =ROUND('① Hypothèses'!B67*(1+'① Hypothèses'!B55),0) -> 15300 | T17: =ROUND('① Hypothèses'!B67*(1+'① Hypothèses'!B55),0) -> 15300 | U17: =ROUND('① Hypothèses'!B67*(1+'① Hypothèses'!B55),0) -> 15300 | V17: =ROUND('① Hypothèses'!B67*(1+'① Hypothèses'!B55),0) -> 15300 | W17: =ROUND('① Hypothèses'!B67*(1+'① Hypothèses'!B55),0) -> 15300 | X17: =ROUND('① Hypothèses'!B67*(1+'① Hypothèses'!B55),0) -> 15300 | Y17: =ROUND('① Hypothèses'!B67*(1+'① Hypothèses'!B55),0) -> 15300 | Z17: =ROUND('① Hypothèses'!B67*(1+'① Hypothèses'!B55),0) -> 15300 | AA17: =ROUND('① Hypothèses'!B67*(1+'① Hypothèses'!B55),0) -> 15300 | AB17: =ROUND('① Hypothèses'!B67*(1+'① Hypothèses'!B55),0) -> 15300 | AC17: =SUM(Q17,R17,S17,T17,U17,V17,W17,X17,Y17,Z17,AA17,AB17) -> 183600 | AE17: =ROUND('① Hypothèses'!B67*(1+'① Hypothèses'!B55)^2,0) -> 15606 | AF17: =ROUND('① Hypothèses'!B67*(1+'① Hypothèses'!B55)^2,0) -> 15606 | AG17: =ROUND('① Hypothèses'!B67*(1+'① Hypothèses'!B55)^2,0) -> 15606 | AH17: =ROUND('① Hypothèses'!B67*(1+'① Hypothèses'!B55)^2,0) -> 15606 | AI17: =ROUND('① Hypothèses'!B67*(1+'① Hypothèses'!B55)^2,0) -> 15606 | AJ17: =ROUND('① Hypothèses'!B67*(1+'① Hypothèses'!B55)^2,0) -> 15606 | AK17: =ROUND('① Hypothèses'!B67*(1+'① Hypothèses'!B55)^2,0) -> 15606 | AL17: =ROUND('① Hypothèses'!B67*(1+'① Hypothèses'!B55)^2,0) -> 15606 | AM17: =ROUND('① Hypothèses'!B67*(1+'① Hypothèses'!B55)^2,0) -> 15606 | AN17: =ROUND('① Hypothèses'!B67*(1+'① Hypothèses'!B55)^2,0) -> 15606 | AO17: =ROUND('① Hypothèses'!B67*(1+'① Hypothèses'!B55)^2,0) -> 15606 | AP17: =ROUND('① Hypothèses'!B67*(1+'① Hypothèses'!B55)^2,0) -> 15606 | AQ17: =SUM(AE17,AF17,AG17,AH17,AI17,AJ17,AK17,AL17,AM17,AN17,AO17,AP17) -> 187272
A18: Entretien & maintenance | C18: =ROUND('① Hypothèses'!B68/12,0) -> 5833 | D18: =ROUND('① Hypothèses'!B68/12,0) -> 5833 | E18: =ROUND('① Hypothèses'!B68/12,0) -> 5833 | F18: =ROUND('① Hypothèses'!B68/12,0) -> 5833 | G18: =ROUND('① Hypothèses'!B68/12,0) -> 5833 | H18: =ROUND('① Hypothèses'!B68/12,0) -> 5833 | I18: =ROUND('① Hypothèses'!B68/12,0) -> 5833 | J18: =ROUND('① Hypothèses'!B68/12,0) -> 5833 | K18: =ROUND('① Hypothèses'!B68/12,0) -> 5833 | L18: =ROUND('① Hypothèses'!B68/12,0) -> 5833 | M18: =ROUND('① Hypothèses'!B68/12,0) -> 5833 | N18: =ROUND('① Hypothèses'!B68/12,0) -> 5833 | O18: =SUM(C18,D18,E18,F18,G18,H18,I18,J18,K18,L18,M18,N18) -> 69996 | Q18: =ROUND('① Hypothèses'!B68/12*(1+'① Hypothèses'!B55),0) -> 5950 | R18: =ROUND('① Hypothèses'!B68/12*(1+'① Hypothèses'!B55),0) -> 5950 | S18: =ROUND('① Hypothèses'!B68/12*(1+'① Hypothèses'!B55),0) -> 5950 | T18: =ROUND('① Hypothèses'!B68/12*(1+'① Hypothèses'!B55),0) -> 5950 | U18: =ROUND('① Hypothèses'!B68/12*(1+'① Hypothèses'!B55),0) -> 5950 | V18: =ROUND('① Hypothèses'!B68/12*(1+'① Hypothèses'!B55),0) -> 5950 | W18: =ROUND('① Hypothèses'!B68/12*(1+'① Hypothèses'!B55),0) -> 5950 | X18: =ROUND('① Hypothèses'!B68/12*(1+'① Hypothèses'!B55),0) -> 5950 | Y18: =ROUND('① Hypothèses'!B68/12*(1+'① Hypothèses'!B55),0) -> 5950 | Z18: =ROUND('① Hypothèses'!B68/12*(1+'① Hypothèses'!B55),0) -> 5950 | AA18: =ROUND('① Hypothèses'!B68/12*(1+'① Hypothèses'!B55),0) -> 5950 | AB18: =ROUND('① Hypothèses'!B68/12*(1+'① Hypothèses'!B55),0) -> 5950 | AC18: =SUM(Q18,R18,S18,T18,U18,V18,W18,X18,Y18,Z18,AA18,AB18) -> 71400 | AE18: =ROUND('① Hypothèses'!B68/12*(1+'① Hypothèses'!B55)^2,0) -> 6069 | AF18: =ROUND('① Hypothèses'!B68/12*(1+'① Hypothèses'!B55)^2,0) -> 6069 | AG18: =ROUND('① Hypothèses'!B68/12*(1+'① Hypothèses'!B55)^2,0) -> 6069 | AH18: =ROUND('① Hypothèses'!B68/12*(1+'① Hypothèses'!B55)^2,0) -> 6069 | AI18: =ROUND('① Hypothèses'!B68/12*(1+'① Hypothèses'!B55)^2,0) -> 6069 | AJ18: =ROUND('① Hypothèses'!B68/12*(1+'① Hypothèses'!B55)^2,0) -> 6069 | AK18: =ROUND('① Hypothèses'!B68/12*(1+'① Hypothèses'!B55)^2,0) -> 6069 | AL18: =ROUND('① Hypothèses'!B68/12*(1+'① Hypothèses'!B55)^2,0) -> 6069 | AM18: =ROUND('① Hypothèses'!B68/12*(1+'① Hypothèses'!B55)^2,0) -> 6069 | AN18: =ROUND('① Hypothèses'!B68/12*(1+'① Hypothèses'!B55)^2,0) -> 6069 | AO18: =ROUND('① Hypothèses'!B68/12*(1+'① Hypothèses'!B55)^2,0) -> 6069 | AP18: =ROUND('① Hypothèses'!B68/12*(1+'① Hypothèses'!B55)^2,0) -> 6069 | AQ18: =SUM(AE18,AF18,AG18,AH18,AI18,AJ18,AK18,AL18,AM18,AN18,AO18,AP18) -> 72828
A19: Marketing & communication | C19: =ROUND('① Hypothèses'!B69/12,0) -> 4167 | D19: =ROUND('① Hypothèses'!B69/12,0) -> 4167 | E19: =ROUND('① Hypothèses'!B69/12,0) -> 4167 | F19: =ROUND('① Hypothèses'!B69/12,0) -> 4167 | G19: =ROUND('① Hypothèses'!B69/12,0) -> 4167 | H19: =ROUND('① Hypothèses'!B69/12,0) -> 4167 | I19: =ROUND('① Hypothèses'!B69/12,0) -> 4167 | J19: =ROUND('① Hypothèses'!B69/12,0) -> 4167 | K19: =ROUND('① Hypothèses'!B69/12,0) -> 4167 | L19: =ROUND('① Hypothèses'!B69/12,0) -> 4167 | M19: =ROUND('① Hypothèses'!B69/12,0) -> 4167 | N19: =ROUND('① Hypothèses'!B69/12,0) -> 4167 | O19: =SUM(C19,D19,E19,F19,G19,H19,I19,J19,K19,L19,M19,N19) -> 50004 | Q19: =ROUND('① Hypothèses'!B69/12*(1+'① Hypothèses'!B55),0) -> 4250 | R19: =ROUND('① Hypothèses'!B69/12*(1+'① Hypothèses'!B55),0) -> 4250 | S19: =ROUND('① Hypothèses'!B69/12*(1+'① Hypothèses'!B55),0) -> 4250 | T19: =ROUND('① Hypothèses'!B69/12*(1+'① Hypothèses'!B55),0) -> 4250 | U19: =ROUND('① Hypothèses'!B69/12*(1+'① Hypothèses'!B55),0) -> 4250 | V19: =ROUND('① Hypothèses'!B69/12*(1+'① Hypothèses'!B55),0) -> 4250 | W19: =ROUND('① Hypothèses'!B69/12*(1+'① Hypothèses'!B55),0) -> 4250 | X19: =ROUND('① Hypothèses'!B69/12*(1+'① Hypothèses'!B55),0) -> 4250 | Y19: =ROUND('① Hypothèses'!B69/12*(1+'① Hypothèses'!B55),0) -> 4250 | Z19: =ROUND('① Hypothèses'!B69/12*(1+'① Hypothèses'!B55),0) -> 4250 | AA19: =ROUND('① Hypothèses'!B69/12*(1+'① Hypothèses'!B55),0) -> 4250 | AB19: =ROUND('① Hypothèses'!B69/12*(1+'① Hypothèses'!B55),0) -> 4250 | AC19: =SUM(Q19,R19,S19,T19,U19,V19,W19,X19,Y19,Z19,AA19,AB19) -> 51000 | AE19: =ROUND('① Hypothèses'!B69/12*(1+'① Hypothèses'!B55)^2,0) -> 4335 | AF19: =ROUND('① Hypothèses'!B69/12*(1+'① Hypothèses'!B55)^2,0) -> 4335 | AG19: =ROUND('① Hypothèses'!B69/12*(1+'① Hypothèses'!B55)^2,0) -> 4335 | AH19: =ROUND('① Hypothèses'!B69/12*(1+'① Hypothèses'!B55)^2,0) -> 4335 | AI19: =ROUND('① Hypothèses'!B69/12*(1+'① Hypothèses'!B55)^2,0) -> 4335 | AJ19: =ROUND('① Hypothèses'!B69/12*(1+'① Hypothèses'!B55)^2,0) -> 4335 | AK19: =ROUND('① Hypothèses'!B69/12*(1+'① Hypothèses'!B55)^2,0) -> 4335 | AL19: =ROUND('① Hypothèses'!B69/12*(1+'① Hypothèses'!B55)^2,0) -> 4335 | AM19: =ROUND('① Hypothèses'!B69/12*(1+'① Hypothèses'!B55)^2,0) -> 4335 | AN19: =ROUND('① Hypothèses'!B69/12*(1+'① Hypothèses'!B55)^2,0) -> 4335 | AO19: =ROUND('① Hypothèses'!B69/12*(1+'① Hypothèses'!B55)^2,0) -> 4335 | AP19: =ROUND('① Hypothèses'!B69/12*(1+'① Hypothèses'!B55)^2,0) -> 4335 | AQ19: =SUM(AE19,AF19,AG19,AH19,AI19,AJ19,AK19,AL19,AM19,AN19,AO19,AP19) -> 52020
A20: Fournitures & linge | C20: =ROUND('① Hypothèses'!B70/12,0) -> 3750 | D20: =ROUND('① Hypothèses'!B70/12,0) -> 3750 | E20: =ROUND('① Hypothèses'!B70/12,0) -> 3750 | F20: =ROUND('① Hypothèses'!B70/12,0) -> 3750 | G20: =ROUND('① Hypothèses'!B70/12,0) -> 3750 | H20: =ROUND('① Hypothèses'!B70/12,0) -> 3750 | I20: =ROUND('① Hypothèses'!B70/12,0) -> 3750 | J20: =ROUND('① Hypothèses'!B70/12,0) -> 3750 | K20: =ROUND('① Hypothèses'!B70/12,0) -> 3750 | L20: =ROUND('① Hypothèses'!B70/12,0) -> 3750 | M20: =ROUND('① Hypothèses'!B70/12,0) -> 3750 | N20: =ROUND('① Hypothèses'!B70/12,0) -> 3750 | O20: =SUM(C20,D20,E20,F20,G20,H20,I20,J20,K20,L20,M20,N20) -> 45000 | Q20: =ROUND('① Hypothèses'!B70/12*(1+'① Hypothèses'!B55),0) -> 3825 | R20: =ROUND('① Hypothèses'!B70/12*(1+'① Hypothèses'!B55),0) -> 3825 | S20: =ROUND('① Hypothèses'!B70/12*(1+'① Hypothèses'!B55),0) -> 3825 | T20: =ROUND('① Hypothèses'!B70/12*(1+'① Hypothèses'!B55),0) -> 3825 | U20: =ROUND('① Hypothèses'!B70/12*(1+'① Hypothèses'!B55),0) -> 3825 | V20: =ROUND('① Hypothèses'!B70/12*(1+'① Hypothèses'!B55),0) -> 3825 | W20: =ROUND('① Hypothèses'!B70/12*(1+'① Hypothèses'!B55),0) -> 3825 | X20: =ROUND('① Hypothèses'!B70/12*(1+'① Hypothèses'!B55),0) -> 3825 | Y20: =ROUND('① Hypothèses'!B70/12*(1+'① Hypothèses'!B55),0) -> 3825 | Z20: =ROUND('① Hypothèses'!B70/12*(1+'① Hypothèses'!B55),0) -> 3825 | AA20: =ROUND('① Hypothèses'!B70/12*(1+'① Hypothèses'!B55),0) -> 3825 | AB20: =ROUND('① Hypothèses'!B70/12*(1+'① Hypothèses'!B55),0) -> 3825 | AC20: =SUM(Q20,R20,S20,T20,U20,V20,W20,X20,Y20,Z20,AA20,AB20) -> 45900 | AE20: =ROUND('① Hypothèses'!B70/12*(1+'① Hypothèses'!B55)^2,0) -> 3902 | AF20: =ROUND('① Hypothèses'!B70/12*(1+'① Hypothèses'!B55)^2,0) -> 3902 | AG20: =ROUND('① Hypothèses'!B70/12*(1+'① Hypothèses'!B55)^2,0) -> 3902 | AH20: =ROUND('① Hypothèses'!B70/12*(1+'① Hypothèses'!B55)^2,0) -> 3902 | AI20: =ROUND('① Hypothèses'!B70/12*(1+'① Hypothèses'!B55)^2,0) -> 3902 | AJ20: =ROUND('① Hypothèses'!B70/12*(1+'① Hypothèses'!B55)^2,0) -> 3902 | AK20: =ROUND('① Hypothèses'!B70/12*(1+'① Hypothèses'!B55)^2,0) -> 3902 | AL20: =ROUND('① Hypothèses'!B70/12*(1+'① Hypothèses'!B55)^2,0) -> 3902 | AM20: =ROUND('① Hypothèses'!B70/12*(1+'① Hypothèses'!B55)^2,0) -> 3902 | AN20: =ROUND('① Hypothèses'!B70/12*(1+'① Hypothèses'!B55)^2,0) -> 3902 | AO20: =ROUND('① Hypothèses'!B70/12*(1+'① Hypothèses'!B55)^2,0) -> 3902 | AP20: =ROUND('① Hypothèses'!B70/12*(1+'① Hypothèses'!B55)^2,0) -> 3902 | AQ20: =SUM(AE20,AF20,AG20,AH20,AI20,AJ20,AK20,AL20,AM20,AN20,AO20,AP20) -> 46824
A21: Expert-comptable | C21: =ROUND('① Hypothèses'!B71/12,0) -> 5417 | D21: =ROUND('① Hypothèses'!B71/12,0) -> 5417 | E21: =ROUND('① Hypothèses'!B71/12,0) -> 5417 | F21: =ROUND('① Hypothèses'!B71/12,0) -> 5417 | G21: =ROUND('① Hypothèses'!B71/12,0) -> 5417 | H21: =ROUND('① Hypothèses'!B71/12,0) -> 5417 | I21: =ROUND('① Hypothèses'!B71/12,0) -> 5417 | J21: =ROUND('① Hypothèses'!B71/12,0) -> 5417 | K21: =ROUND('① Hypothèses'!B71/12,0) -> 5417 | L21: =ROUND('① Hypothèses'!B71/12,0) -> 5417 | M21: =ROUND('① Hypothèses'!B71/12,0) -> 5417 | N21: =ROUND('① Hypothèses'!B71/12,0) -> 5417 | O21: =SUM(C21,D21,E21,F21,G21,H21,I21,J21,K21,L21,M21,N21) -> 65004 | Q21: =ROUND('① Hypothèses'!B71/12,0) -> 5417 | R21: =ROUND('① Hypothèses'!B71/12,0) -> 5417 | S21: =ROUND('① Hypothèses'!B71/12,0) -> 5417 | T21: =ROUND('① Hypothèses'!B71/12,0) -> 5417 | U21: =ROUND('① Hypothèses'!B71/12,0) -> 5417 | V21: =ROUND('① Hypothèses'!B71/12,0) -> 5417 | W21: =ROUND('① Hypothèses'!B71/12,0) -> 5417 | X21: =ROUND('① Hypothèses'!B71/12,0) -> 5417 | Y21: =ROUND('① Hypothèses'!B71/12,0) -> 5417 | Z21: =ROUND('① Hypothèses'!B71/12,0) -> 5417 | AA21: =ROUND('① Hypothèses'!B71/12,0) -> 5417 | AB21: =ROUND('① Hypothèses'!B71/12,0) -> 5417 | AC21: =SUM(Q21,R21,S21,T21,U21,V21,W21,X21,Y21,Z21,AA21,AB21) -> 65004 | AE21: =ROUND('① Hypothèses'!B71/12,0) -> 5417 | AF21: =ROUND('① Hypothèses'!B71/12,0) -> 5417 | AG21: =ROUND('① Hypothèses'!B71/12,0) -> 5417 | AH21: =ROUND('① Hypothèses'!B71/12,0) -> 5417 | AI21: =ROUND('① Hypothèses'!B71/12,0) -> 5417 | AJ21: =ROUND('① Hypothèses'!B71/12,0) -> 5417 | AK21: =ROUND('① Hypothèses'!B71/12,0) -> 5417 | AL21: =ROUND('① Hypothèses'!B71/12,0) -> 5417 | AM21: =ROUND('① Hypothèses'!B71/12,0) -> 5417 | AN21: =ROUND('① Hypothèses'!B71/12,0) -> 5417 | AO21: =ROUND('① Hypothèses'!B71/12,0) -> 5417 | AP21: =ROUND('① Hypothèses'!B71/12,0) -> 5417 | AQ21: =SUM(AE21,AF21,AG21,AH21,AI21,AJ21,AK21,AL21,AM21,AN21,AO21,AP21) -> 65004
A22: Autres charges externes | C22: =ROUND('① Hypothèses'!B72/12,0) -> 8333 | D22: =ROUND('① Hypothèses'!B72/12,0) -> 8333 | E22: =ROUND('① Hypothèses'!B72/12,0) -> 8333 | F22: =ROUND('① Hypothèses'!B72/12,0) -> 8333 | G22: =ROUND('① Hypothèses'!B72/12,0) -> 8333 | H22: =ROUND('① Hypothèses'!B72/12,0) -> 8333 | I22: =ROUND('① Hypothèses'!B72/12,0) -> 8333 | J22: =ROUND('① Hypothèses'!B72/12,0) -> 8333 | K22: =ROUND('① Hypothèses'!B72/12,0) -> 8333 | L22: =ROUND('① Hypothèses'!B72/12,0) -> 8333 | M22: =ROUND('① Hypothèses'!B72/12,0) -> 8333 | N22: =ROUND('① Hypothèses'!B72/12,0) -> 8333 | O22: =SUM(C22,D22,E22,F22,G22,H22,I22,J22,K22,L22,M22,N22) -> 99996 | Q22: =ROUND('① Hypothèses'!B72/12*(1+'① Hypothèses'!B55),0) -> 8500 | R22: =ROUND('① Hypothèses'!B72/12*(1+'① Hypothèses'!B55),0) -> 8500 | S22: =ROUND('① Hypothèses'!B72/12*(1+'① Hypothèses'!B55),0) -> 8500 | T22: =ROUND('① Hypothèses'!B72/12*(1+'① Hypothèses'!B55),0) -> 8500 | U22: =ROUND('① Hypothèses'!B72/12*(1+'① Hypothèses'!B55),0) -> 8500 | V22: =ROUND('① Hypothèses'!B72/12*(1+'① Hypothèses'!B55),0) -> 8500 | W22: =ROUND('① Hypothèses'!B72/12*(1+'① Hypothèses'!B55),0) -> 8500 | X22: =ROUND('① Hypothèses'!B72/12*(1+'① Hypothèses'!B55),0) -> 8500 | Y22: =ROUND('① Hypothèses'!B72/12*(1+'① Hypothèses'!B55),0) -> 8500 | Z22: =ROUND('① Hypothèses'!B72/12*(1+'① Hypothèses'!B55),0) -> 8500 | AA22: =ROUND('① Hypothèses'!B72/12*(1+'① Hypothèses'!B55),0) -> 8500 | AB22: =ROUND('① Hypothèses'!B72/12*(1+'① Hypothèses'!B55),0) -> 8500 | AC22: =SUM(Q22,R22,S22,T22,U22,V22,W22,X22,Y22,Z22,AA22,AB22) -> 102000 | AE22: =ROUND('① Hypothèses'!B72/12*(1+'① Hypothèses'!B55)^2,0) -> 8670 | AF22: =ROUND('① Hypothèses'!B72/12*(1+'① Hypothèses'!B55)^2,0) -> 8670 | AG22: =ROUND('① Hypothèses'!B72/12*(1+'① Hypothèses'!B55)^2,0) -> 8670 | AH22: =ROUND('① Hypothèses'!B72/12*(1+'① Hypothèses'!B55)^2,0) -> 8670 | AI22: =ROUND('① Hypothèses'!B72/12*(1+'① Hypothèses'!B55)^2,0) -> 8670 | AJ22: =ROUND('① Hypothèses'!B72/12*(1+'① Hypothèses'!B55)^2,0) -> 8670 | AK22: =ROUND('① Hypothèses'!B72/12*(1+'① Hypothèses'!B55)^2,0) -> 8670 | AL22: =ROUND('① Hypothèses'!B72/12*(1+'① Hypothèses'!B55)^2,0) -> 8670 | AM22: =ROUND('① Hypothèses'!B72/12*(1+'① Hypothèses'!B55)^2,0) -> 8670 | AN22: =ROUND('① Hypothèses'!B72/12*(1+'① Hypothèses'!B55)^2,0) -> 8670 | AO22: =ROUND('① Hypothèses'!B72/12*(1+'① Hypothèses'!B55)^2,0) -> 8670 | AP22: =ROUND('① Hypothèses'!B72/12*(1+'① Hypothèses'!B55)^2,0) -> 8670 | AQ22: =SUM(AE22,AF22,AG22,AH22,AI22,AJ22,AK22,AL22,AM22,AN22,AO22,AP22) -> 104040
A23: Impôts & taxes locaux | C23: =ROUND('① Hypothèses'!B73/12,0) -> 10000 | D23: =ROUND('① Hypothèses'!B73/12,0) -> 10000 | E23: =ROUND('① Hypothèses'!B73/12,0) -> 10000 | F23: =ROUND('① Hypothèses'!B73/12,0) -> 10000 | G23: =ROUND('① Hypothèses'!B73/12,0) -> 10000 | H23: =ROUND('① Hypothèses'!B73/12,0) -> 10000 | I23: =ROUND('① Hypothèses'!B73/12,0) -> 10000 | J23: =ROUND('① Hypothèses'!B73/12,0) -> 10000 | K23: =ROUND('① Hypothèses'!B73/12,0) -> 10000 | L23: =ROUND('① Hypothèses'!B73/12,0) -> 10000 | M23: =ROUND('① Hypothèses'!B73/12,0) -> 10000 | N23: =ROUND('① Hypothèses'!B73/12,0) -> 10000 | O23: =SUM(C23,D23,E23,F23,G23,H23,I23,J23,K23,L23,M23,N23) -> 120000 | Q23: =ROUND('① Hypothèses'!B73/12,0) -> 10000 | R23: =ROUND('① Hypothèses'!B73/12,0) -> 10000 | S23: =ROUND('① Hypothèses'!B73/12,0) -> 10000 | T23: =ROUND('① Hypothèses'!B73/12,0) -> 10000 | U23: =ROUND('① Hypothèses'!B73/12,0) -> 10000 | V23: =ROUND('① Hypothèses'!B73/12,0) -> 10000 | W23: =ROUND('① Hypothèses'!B73/12,0) -> 10000 | X23: =ROUND('① Hypothèses'!B73/12,0) -> 10000 | Y23: =ROUND('① Hypothèses'!B73/12,0) -> 10000 | Z23: =ROUND('① Hypothèses'!B73/12,0) -> 10000 | AA23: =ROUND('① Hypothèses'!B73/12,0) -> 10000 | AB23: =ROUND('① Hypothèses'!B73/12,0) -> 10000 | AC23: =SUM(Q23,R23,S23,T23,U23,V23,W23,X23,Y23,Z23,AA23,AB23) -> 120000 | AE23: =ROUND('① Hypothèses'!B73/12,0) -> 10000 | AF23: =ROUND('① Hypothèses'!B73/12,0) -> 10000 | AG23: =ROUND('① Hypothèses'!B73/12,0) -> 10000 | AH23: =ROUND('① Hypothèses'!B73/12,0) -> 10000 | AI23: =ROUND('① Hypothèses'!B73/12,0) -> 10000 | AJ23: =ROUND('① Hypothèses'!B73/12,0) -> 10000 | AK23: =ROUND('① Hypothèses'!B73/12,0) -> 10000 | AL23: =ROUND('① Hypothèses'!B73/12,0) -> 10000 | AM23: =ROUND('① Hypothèses'!B73/12,0) -> 10000 | AN23: =ROUND('① Hypothèses'!B73/12,0) -> 10000 | AO23: =ROUND('① Hypothèses'!B73/12,0) -> 10000 | AP23: =ROUND('① Hypothèses'!B73/12,0) -> 10000 | AQ23: =SUM(AE23,AF23,AG23,AH23,AI23,AJ23,AK23,AL23,AM23,AN23,AO23,AP23) -> 120000
